<robot name="opendog">
<link name="body">
<visual>
<origin xyz="0.198056 -0.249363 0.0714268" rpy="2.45786e-15 -3.86847e-24 6.38026e-10" />
<geometry>
<mesh filename="package://body_22.stl"/>
</geometry>
<material name="body_22_material">
<color rgba="0.231373 0.380392 0.705882 1.0"/>
</material>
</visual>
<collision>
<origin xyz="0.198056 -0.249363 0.0714268" rpy="2.45786e-15 -3.86847e-24 6.38026e-10" />
<geometry>
<mesh filename="package://body_22.stl"/>
</geometry>
<material name="body_22_material">
<color rgba="0.231373 0.380392 0.705882 1.0"/>
</material>
</collision>
<visual>
<origin xyz="0.184442 -0.250039 0.0752002" rpy="2.17426e-15 -3.86847e-24 6.38015e-10" />
<geometry>
<mesh filename="package://body_24.stl"/>
</geometry>
<material name="body_24_material">
<color rgba="0.231373 0.380392 0.705882 1.0"/>
</material>
</visual>
<collision>
<origin xyz="0.184442 -0.250039 0.0752002" rpy="2.17426e-15 -3.86847e-24 6.38015e-10" />
<geometry>
<mesh filename="package://body_24.stl"/>
</geometry>
<material name="body_24_material">
<color rgba="0.231373 0.380392 0.705882 1.0"/>
</material>
</collision>
<visual>
<origin xyz="0.197422 -0.250033 0.0714335" rpy="2.67606e-16 -3.86847e-24 6.38026e-10" />
<geometry>
<mesh filename="package://body_31.stl"/>
</geometry>
<material name="body_31_material">
<color rgba="0.231373 0.380392 0.705882 1.0"/>
</material>
</visual>
<collision>
<origin xyz="0.197422 -0.250033 0.0714335" rpy="2.67606e-16 -3.86847e-24 6.38026e-10" />
<geometry>
<mesh filename="package://body_31.stl"/>
</geometry>
<material name="body_31_material">
<color rgba="0.231373 0.380392 0.705882 1.0"/>
</material>
</collision>
<visual>
<origin xyz="0.184056 -0.249471 0.0752002" rpy="2.17426e-15 -3.86847e-24 6.38026e-10" />
<geometry>
<mesh filename="package://body_25.stl"/>
</geometry>
<material name="body_25_material">
<color rgba="0.231373 0.380392 0.705882 1.0"/>
</material>
</visual>
<collision>
<origin xyz="0.184056 -0.249471 0.0752002" rpy="2.17426e-15 -3.86847e-24 6.38026e-10" />
<geometry>
<mesh filename="package://body_25.stl"/>
</geometry>
<material name="body_25_material">
<color rgba="0.231373 0.380392 0.705882 1.0"/>
</material>
</collision>
<visual>
<origin xyz="0.183422 -0.250141 0.0752069" rpy="-1.59986e-17 -3.86847e-24 6.38027e-10" />
<geometry>
<mesh filename="package://body_32.stl"/>
</geometry>
<material name="body_32_material">
<color rgba="0.231373 0.380392 0.705882 1.0"/>
</material>
</visual>
<collision>
<origin xyz="0.183422 -0.250141 0.0752069" rpy="-1.59986e-17 -3.86847e-24 6.38027e-10" />
<geometry>
<mesh filename="package://body_32.stl"/>
</geometry>
<material name="body_32_material">
<color rgba="0.231373 0.380392 0.705882 1.0"/>
</material>
</collision>
<visual>
<origin xyz="0.18329 -0.249818 0.0752069" rpy="-5.95504e-15 -3.86848e-24 6.38038e-10" />
<geometry>
<mesh filename="package://body_1.stl"/>
</geometry>
<material name="body_1_material">
<color rgba="0.231373 0.380392 0.705882 1.0"/>
</material>
</visual>
<collision>
<origin xyz="0.18329 -0.249818 0.0752069" rpy="-5.95504e-15 -3.86848e-24 6.38038e-10" />
<geometry>
<mesh filename="package://body_1.stl"/>
</geometry>
<material name="body_1_material">
<color rgba="0.231373 0.380392 0.705882 1.0"/>
</material>
</collision>
<visual>
<origin xyz="0.18444 -0.250033 0.0752069" rpy="-1.36772e-16 -3.86847e-24 6.38026e-10" />
<geometry>
<mesh filename="package://body_30.stl"/>
</geometry>
<material name="body_30_material">
<color rgba="0.231373 0.380392 0.705882 1.0"/>
</material>
</visual>
<collision>
<origin xyz="0.18444 -0.250033 0.0752069" rpy="-1.36772e-16 -3.86847e-24 6.38026e-10" />
<geometry>
<mesh filename="package://body_30.stl"/>
</geometry>
<material name="body_30_material">
<color rgba="0.231373 0.380392 0.705882 1.0"/>
</material>
</collision>
<visual>
<origin xyz="0.18329 -0.250033 0.0752069" rpy="6.49194e-15 -3.86847e-24 6.38014e-10" />
<geometry>
<mesh filename="package://body_6.stl"/>
</geometry>
<material name="body_6_material">
<color rgba="0.231373 0.380392 0.705882 1.0"/>
</material>
</visual>
<collision>
<origin xyz="0.18329 -0.250033 0.0752069" rpy="6.49194e-15 -3.86847e-24 6.38014e-10" />
<geometry>
<mesh filename="package://body_6.stl"/>
</geometry>
<material name="body_6_material">
<color rgba="0.231373 0.380392 0.705882 1.0"/>
</material>
</collision>
<visual>
<origin xyz="0.183706 -0.250039 0.0752002" rpy="2.17426e-15 -3.86847e-24 6.38034e-10" />
<geometry>
<mesh filename="package://body_28.stl"/>
</geometry>
<material name="body_28_material">
<color rgba="0.231373 0.380392 0.705882 1.0"/>
</material>
</visual>
<collision>
<origin xyz="0.183706 -0.250039 0.0752002" rpy="2.17426e-15 -3.86847e-24 6.38034e-10" />
<geometry>
<mesh filename="package://body_28.stl"/>
</geometry>
<material name="body_28_material">
<color rgba="0.231373 0.380392 0.705882 1.0"/>
</material>
</collision>
<visual>
<origin xyz="0.18444 -0.249926 0.0752069" rpy="8.26342e-14 -3.86848e-24 6.38062e-10" />
<geometry>
<mesh filename="package://body_11.stl"/>
</geometry>
<material name="body_11_material">
<color rgba="0.231373 0.380392 0.705882 1.0"/>
</material>
</visual>
<collision>
<origin xyz="0.18444 -0.249926 0.0752069" rpy="8.26342e-14 -3.86848e-24 6.38062e-10" />
<geometry>
<mesh filename="package://body_11.stl"/>
</geometry>
<material name="body_11_material">
<color rgba="0.231373 0.380392 0.705882 1.0"/>
</material>
</collision>
<visual>
<origin xyz="0.183706 -0.250147 0.0752002" rpy="2.05348e-15 -3.86847e-24 6.38034e-10" />
<geometry>
<mesh filename="package://body_27.stl"/>
</geometry>
<material name="body_27_material">
<color rgba="0.231373 0.380392 0.705882 1.0"/>
</material>
</visual>
<collision>
<origin xyz="0.183706 -0.250147 0.0752002" rpy="2.05348e-15 -3.86847e-24 6.38034e-10" />
<geometry>
<mesh filename="package://body_27.stl"/>
</geometry>
<material name="body_27_material">
<color rgba="0.231373 0.380392 0.705882 1.0"/>
</material>
</collision>
<visual>
<origin xyz="0.184422 -0.250033 0.0752069" rpy="-8.26645e-14 -3.86848e-24 6.38063e-10" />
<geometry>
<mesh filename="package://body_16.stl"/>
</geometry>
<material name="body_16_material">
<color rgba="0.231373 0.380392 0.705882 1.0"/>
</material>
</visual>
<collision>
<origin xyz="0.184422 -0.250033 0.0752069" rpy="-8.26645e-14 -3.86848e-24 6.38063e-10" />
<geometry>
<mesh filename="package://body_16.stl"/>
</geometry>
<material name="body_16_material">
<color rgba="0.231373 0.380392 0.705882 1.0"/>
</material>
</collision>
<visual>
<origin xyz="0.18444 -0.250033 0.0764786" rpy="6.20834e-15 -3.86847e-24 6.38015e-10" />
<geometry>
<mesh filename="package://body_8.stl"/>
</geometry>
<material name="body_8_material">
<color rgba="0.231373 0.380392 0.705882 1.0"/>
</material>
</visual>
<collision>
<origin xyz="0.18444 -0.250033 0.0764786" rpy="6.20834e-15 -3.86847e-24 6.38015e-10" />
<geometry>
<mesh filename="package://body_8.stl"/>
</geometry>
<material name="body_8_material">
<color rgba="0.231373 0.380392 0.705882 1.0"/>
</material>
</collision>
<visual>
<origin xyz="0.18444 -0.250033 0.0752069" rpy="6.20834e-15 -3.86847e-24 6.38015e-10" />
<geometry>
<mesh filename="package://body_5.stl"/>
</geometry>
<material name="body_5_material">
<color rgba="0.231373 0.380392 0.705882 1.0"/>
</material>
</visual>
<collision>
<origin xyz="0.18444 -0.250033 0.0752069" rpy="6.20834e-15 -3.86847e-24 6.38015e-10" />
<geometry>
<mesh filename="package://body_5.stl"/>
</geometry>
<material name="body_5_material">
<color rgba="0.231373 0.380392 0.705882 1.0"/>
</material>
</collision>
<visual>
<origin xyz="0.198056 -0.249363 0.0714268" rpy="2.45786e-15 -3.86847e-24 6.38026e-10" />
<geometry>
<mesh filename="package://body_21.stl"/>
</geometry>
<material name="body_21_material">
<color rgba="0.231373 0.380392 0.705882 1.0"/>
</material>
</visual>
<collision>
<origin xyz="0.198056 -0.249363 0.0714268" rpy="2.45786e-15 -3.86847e-24 6.38026e-10" />
<geometry>
<mesh filename="package://body_21.stl"/>
</geometry>
<material name="body_21_material">
<color rgba="0.231373 0.380392 0.705882 1.0"/>
</material>
</collision>
<visual>
<origin xyz="0.184442 -0.250147 0.0752002" rpy="2.05348e-15 -3.86847e-24 6.38015e-10" />
<geometry>
<mesh filename="package://body_26.stl"/>
</geometry>
<material name="body_26_material">
<color rgba="0.231373 0.380392 0.705882 1.0"/>
</material>
</visual>
<collision>
<origin xyz="0.184442 -0.250147 0.0752002" rpy="2.05348e-15 -3.86847e-24 6.38015e-10" />
<geometry>
<mesh filename="package://body_26.stl"/>
</geometry>
<material name="body_26_material">
<color rgba="0.231373 0.380392 0.705882 1.0"/>
</material>
</collision>
<visual>
<origin xyz="0.18444 -0.249925 0.0752069" rpy="-1.59986e-17 -3.86847e-24 6.38027e-10" />
<geometry>
<mesh filename="package://body_14.stl"/>
</geometry>
<material name="body_14_material">
<color rgba="0.231373 0.380392 0.705882 1.0"/>
</material>
</visual>
<collision>
<origin xyz="0.18444 -0.249925 0.0752069" rpy="-1.59986e-17 -3.86847e-24 6.38027e-10" />
<geometry>
<mesh filename="package://body_14.stl"/>
</geometry>
<material name="body_14_material">
<color rgba="0.231373 0.380392 0.705882 1.0"/>
</material>
</collision>
<visual>
<origin xyz="0.184056 -0.249471 0.0752002" rpy="2.17426e-15 -3.86847e-24 6.38027e-10" />
<geometry>
<mesh filename="package://body_29.stl"/>
</geometry>
<material name="body_29_material">
<color rgba="0.231373 0.380392 0.705882 1.0"/>
</material>
</visual>
<collision>
<origin xyz="0.184056 -0.249471 0.0752002" rpy="2.17426e-15 -3.86847e-24 6.38027e-10" />
<geometry>
<mesh filename="package://body_29.stl"/>
</geometry>
<material name="body_29_material">
<color rgba="0.231373 0.380392 0.705882 1.0"/>
</material>
</collision>
<visual>
<origin xyz="0.184422 -0.249817 0.0752069" rpy="2.67606e-16 -3.86847e-24 6.38026e-10" />
<geometry>
<mesh filename="package://body_12.stl"/>
</geometry>
<material name="body_12_material">
<color rgba="0.231373 0.380392 0.705882 1.0"/>
</material>
</visual>
<collision>
<origin xyz="0.184422 -0.249817 0.0752069" rpy="2.67606e-16 -3.86847e-24 6.38026e-10" />
<geometry>
<mesh filename="package://body_12.stl"/>
</geometry>
<material name="body_12_material">
<color rgba="0.231373 0.380392 0.705882 1.0"/>
</material>
</collision>
<visual>
<origin xyz="0.18329 -0.250033 0.0764786" rpy="6.49194e-15 -3.86847e-24 6.38014e-10" />
<geometry>
<mesh filename="package://body_7.stl"/>
</geometry>
<material name="body_7_material">
<color rgba="0.231373 0.380392 0.705882 1.0"/>
</material>
</visual>
<collision>
<origin xyz="0.18329 -0.250033 0.0764786" rpy="6.49194e-15 -3.86847e-24 6.38014e-10" />
<geometry>
<mesh filename="package://body_7.stl"/>
</geometry>
<material name="body_7_material">
<color rgba="0.231373 0.380392 0.705882 1.0"/>
</material>
</collision>
<visual>
<origin xyz="0.18444 -0.250033 0.0752069" rpy="-5.99371e-15 -3.86847e-24 6.38015e-10" />
<geometry>
<mesh filename="package://body_18.stl"/>
</geometry>
<material name="body_18_material">
<color rgba="0.231373 0.380392 0.705882 1.0"/>
</material>
</visual>
<collision>
<origin xyz="0.18444 -0.250033 0.0752069" rpy="-5.99371e-15 -3.86847e-24 6.38015e-10" />
<geometry>
<mesh filename="package://body_18.stl"/>
</geometry>
<material name="body_18_material">
<color rgba="0.231373 0.380392 0.705882 1.0"/>
</material>
</collision>
<visual>
<origin xyz="0.18444 -0.250033 0.0752069" rpy="6.49194e-15 -3.86847e-24 6.38014e-10" />
<geometry>
<mesh filename="package://body_19.stl"/>
</geometry>
<material name="body_19_material">
<color rgba="0.231373 0.380392 0.705882 1.0"/>
</material>
</visual>
<collision>
<origin xyz="0.18444 -0.250033 0.0752069" rpy="6.49194e-15 -3.86847e-24 6.38014e-10" />
<geometry>
<mesh filename="package://body_19.stl"/>
</geometry>
<material name="body_19_material">
<color rgba="0.231373 0.380392 0.705882 1.0"/>
</material>
</collision>
<visual>
<origin xyz="0.18444 -0.249818 0.0752069" rpy="8.29178e-14 -3.86848e-24 6.38062e-10" />
<geometry>
<mesh filename="package://body_9.stl"/>
</geometry>
<material name="body_9_material">
<color rgba="0.231373 0.380392 0.705882 1.0"/>
</material>
</visual>
<collision>
<origin xyz="0.18444 -0.249818 0.0752069" rpy="8.29178e-14 -3.86848e-24 6.38062e-10" />
<geometry>
<mesh filename="package://body_9.stl"/>
</geometry>
<material name="body_9_material">
<color rgba="0.231373 0.380392 0.705882 1.0"/>
</material>
</collision>
<visual>
<origin xyz="0.18444 -0.250033 0.0752069" rpy="6.20834e-15 -3.86847e-24 6.38015e-10" />
<geometry>
<mesh filename="package://body_20.stl"/>
</geometry>
<material name="body_20_material">
<color rgba="0.231373 0.380392 0.705882 1.0"/>
</material>
</visual>
<collision>
<origin xyz="0.18444 -0.250033 0.0752069" rpy="6.20834e-15 -3.86847e-24 6.38015e-10" />
<geometry>
<mesh filename="package://body_20.stl"/>
</geometry>
<material name="body_20_material">
<color rgba="0.231373 0.380392 0.705882 1.0"/>
</material>
</collision>
<visual>
<origin xyz="0.18444 -0.249818 0.0752069" rpy="-6.23864e-15 -3.86847e-24 6.38038e-10" />
<geometry>
<mesh filename="package://body_2.stl"/>
</geometry>
<material name="body_2_material">
<color rgba="0.231373 0.380392 0.705882 1.0"/>
</material>
</visual>
<collision>
<origin xyz="0.18444 -0.249818 0.0752069" rpy="-6.23864e-15 -3.86847e-24 6.38038e-10" />
<geometry>
<mesh filename="package://body_2.stl"/>
</geometry>
<material name="body_2_material">
<color rgba="0.231373 0.380392 0.705882 1.0"/>
</material>
</collision>
<visual>
<origin xyz="0.18444 -0.250033 0.0752069" rpy="-1.43075e-17 -3.86847e-24 6.38027e-10" />
<geometry>
<mesh filename="package://body_15.stl"/>
</geometry>
<material name="body_15_material">
<color rgba="0.231373 0.380392 0.705882 1.0"/>
</material>
</visual>
<collision>
<origin xyz="0.18444 -0.250033 0.0752069" rpy="-1.43075e-17 -3.86847e-24 6.38027e-10" />
<geometry>
<mesh filename="package://body_15.stl"/>
</geometry>
<material name="body_15_material">
<color rgba="0.231373 0.380392 0.705882 1.0"/>
</material>
</collision>
<visual>
<origin xyz="0.184422 -0.249925 0.0752069" rpy="-8.26662e-14 -3.86848e-24 6.38063e-10" />
<geometry>
<mesh filename="package://body_13.stl"/>
</geometry>
<material name="body_13_material">
<color rgba="0.231373 0.380392 0.705882 1.0"/>
</material>
</visual>
<collision>
<origin xyz="0.184422 -0.249925 0.0752069" rpy="-8.26662e-14 -3.86848e-24 6.38063e-10" />
<geometry>
<mesh filename="package://body_13.stl"/>
</geometry>
<material name="body_13_material">
<color rgba="0.231373 0.380392 0.705882 1.0"/>
</material>
</collision>
<visual>
<origin xyz="0.18444 -0.250033 0.0752069" rpy="-5.99202e-15 -3.86847e-24 6.38015e-10" />
<geometry>
<mesh filename="package://body_17.stl"/>
</geometry>
<material name="body_17_material">
<color rgba="0.231373 0.380392 0.705882 1.0"/>
</material>
</visual>
<collision>
<origin xyz="0.18444 -0.250033 0.0752069" rpy="-5.99202e-15 -3.86847e-24 6.38015e-10" />
<geometry>
<mesh filename="package://body_17.stl"/>
</geometry>
<material name="body_17_material">
<color rgba="0.231373 0.380392 0.705882 1.0"/>
</material>
</collision>
<visual>
<origin xyz="0.18444 -0.249818 0.0764786" rpy="-6.23695e-15 -3.86847e-24 6.38038e-10" />
<geometry>
<mesh filename="package://body_3.stl"/>
</geometry>
<material name="body_3_material">
<color rgba="0.231373 0.380392 0.705882 1.0"/>
</material>
</visual>
<collision>
<origin xyz="0.18444 -0.249818 0.0764786" rpy="-6.23695e-15 -3.86847e-24 6.38038e-10" />
<geometry>
<mesh filename="package://body_3.stl"/>
</geometry>
<material name="body_3_material">
<color rgba="0.231373 0.380392 0.705882 1.0"/>
</material>
</collision>
<visual>
<origin xyz="0.18444 -0.249925 0.0752069" rpy="-1.59986e-17 -3.86847e-24 6.38027e-10" />
<geometry>
<mesh filename="package://body_23.stl"/>
</geometry>
<material name="body_23_material">
<color rgba="0.231373 0.380392 0.705882 1.0"/>
</material>
</visual>
<collision>
<origin xyz="0.18444 -0.249925 0.0752069" rpy="-1.59986e-17 -3.86847e-24 6.38027e-10" />
<geometry>
<mesh filename="package://body_23.stl"/>
</geometry>
<material name="body_23_material">
<color rgba="0.231373 0.380392 0.705882 1.0"/>
</material>
</collision>
<visual>
<origin xyz="0.184422 -0.249925 0.0752069" rpy="-1.59986e-17 -3.86847e-24 6.38026e-10" />
<geometry>
<mesh filename="package://body_10.stl"/>
</geometry>
<material name="body_10_material">
<color rgba="0.231373 0.380392 0.705882 1.0"/>
</material>
</visual>
<collision>
<origin xyz="0.184422 -0.249925 0.0752069" rpy="-1.59986e-17 -3.86847e-24 6.38026e-10" />
<geometry>
<mesh filename="package://body_10.stl"/>
</geometry>
<material name="body_10_material">
<color rgba="0.231373 0.380392 0.705882 1.0"/>
</material>
</collision>
<visual>
<origin xyz="0.18329 -0.249818 0.0764786" rpy="-6.23864e-15 -3.86847e-24 6.38038e-10" />
<geometry>
<mesh filename="package://body_4.stl"/>
</geometry>
<material name="body_4_material">
<color rgba="0.231373 0.380392 0.705882 1.0"/>
</material>
</visual>
<collision>
<origin xyz="0.18329 -0.249818 0.0764786" rpy="-6.23864e-15 -3.86847e-24 6.38038e-10" />
<geometry>
<mesh filename="package://body_4.stl"/>
</geometry>
<material name="body_4_material">
<color rgba="0.231373 0.380392 0.705882 1.0"/>
</material>
</collision>
<inertial>
<origin xyz="-0.000406067 -0.000123026 0.0731678" rpy="0 0 0"/>
<mass value="6.64" />
<inertia ixx="0.516106" ixy="0.000773589"  ixz="1.55833e-05" iyy="0.0590665" iyz="0.000494641" izz="0.525166" />
</inertial>
</link>

<link name="hip">
<visual>
<origin xyz="0.0299938 -1.83141e-07 -0.2195" rpy="-1.5708 -1.14907e-16 1.5708" />
<geometry>
<mesh filename="package://ams_3.stl"/>
</geometry>
<material name="ams_3_material">
<color rgba="0.498039 0.498039 0.498039 1.0"/>
</material>
</visual>
<collision>
<origin xyz="0.0299938 -1.83141e-07 -0.2195" rpy="-1.5708 -1.14907e-16 1.5708" />
<geometry>
<mesh filename="package://ams_3.stl"/>
</geometry>
<material name="ams_3_material">
<color rgba="0.498039 0.498039 0.498039 1.0"/>
</material>
</collision>
<visual>
<origin xyz="0.0607598 -0.115907 -0.212439" rpy="-2.35619 7.02848e-15 5.33246e-16" />
<geometry>
<mesh filename="package://hip_16.stl"/>
</geometry>
<material name="hip_16_material">
<color rgba="0.498039 0.498039 0.498039 1.0"/>
</material>
</visual>
<collision>
<origin xyz="0.0607598 -0.115907 -0.212439" rpy="-2.35619 7.02848e-15 5.33246e-16" />
<geometry>
<mesh filename="package://hip_16.stl"/>
</geometry>
<material name="hip_16_material">
<color rgba="0.498039 0.498039 0.498039 1.0"/>
</material>
</collision>
<visual>
<origin xyz="0.0606938 0.00108347 -0.26" rpy="-1.5708 2.09166e-14 9.15934e-16" />
<geometry>
<mesh filename="package://hip_10.stl"/>
</geometry>
<material name="hip_10_material">
<color rgba="0.498039 0.498039 0.498039 1.0"/>
</material>
</visual>
<collision>
<origin xyz="0.0606938 0.00108347 -0.26" rpy="-1.5708 2.09166e-14 9.15934e-16" />
<geometry>
<mesh filename="package://hip_10.stl"/>
</geometry>
<material name="hip_10_material">
<color rgba="0.498039 0.498039 0.498039 1.0"/>
</material>
</collision>
<visual>
<origin xyz="0.0300778 -1.83141e-07 -0.2195" rpy="-1.5708 -1.09074e-16 1.5708" />
<geometry>
<mesh filename="package://ams_4.stl"/>
</geometry>
<material name="ams_4_material">
<color rgba="0.498039 0.498039 0.498039 1.0"/>
</material>
</visual>
<collision>
<origin xyz="0.0300778 -1.83141e-07 -0.2195" rpy="-1.5708 -1.09074e-16 1.5708" />
<geometry>
<mesh filename="package://ams_4.stl"/>
</geometry>
<material name="ams_4_material">
<color rgba="0.498039 0.498039 0.498039 1.0"/>
</material>
</collision>
<visual>
<origin xyz="0.0607598 0.00108347 -0.26" rpy="-1.5708 2.09166e-14 4.16334e-17" />
<geometry>
<mesh filename="package://hip_6.stl"/>
</geometry>
<material name="hip_6_material">
<color rgba="0.498039 0.498039 0.498039 1.0"/>
</material>
</visual>
<collision>
<origin xyz="0.0607598 0.00108347 -0.26" rpy="-1.5708 2.09166e-14 4.16334e-17" />
<geometry>
<mesh filename="package://hip_6.stl"/>
</geometry>
<material name="hip_6_material">
<color rgba="0.498039 0.498039 0.498039 1.0"/>
</material>
</collision>
<visual>
<origin xyz="0.0607598 0.00108347 -0.26" rpy="-1.5708 3.11385e-14 4.16334e-17" />
<geometry>
<mesh filename="package://hip_11.stl"/>
</geometry>
<material name="hip_11_material">
<color rgba="0.498039 0.498039 0.498039 1.0"/>
</material>
</visual>
<collision>
<origin xyz="0.0607598 0.00108347 -0.26" rpy="-1.5708 3.11385e-14 4.16334e-17" />
<geometry>
<mesh filename="package://hip_11.stl"/>
</geometry>
<material name="hip_11_material">
<color rgba="0.498039 0.498039 0.498039 1.0"/>
</material>
</collision>
<visual>
<origin xyz="0.0606938 0.00108347 -0.26" rpy="-1.5708 8.76247e-15 -4.16334e-16" />
<geometry>
<mesh filename="package://hip_3.stl"/>
</geometry>
<material name="hip_3_material">
<color rgba="0.498039 0.498039 0.498039 1.0"/>
</material>
</visual>
<collision>
<origin xyz="0.0606938 0.00108347 -0.26" rpy="-1.5708 8.76247e-15 -4.16334e-16" />
<geometry>
<mesh filename="package://hip_3.stl"/>
</geometry>
<material name="hip_3_material">
<color rgba="0.498039 0.498039 0.498039 1.0"/>
</material>
</collision>
<visual>
<origin xyz="0.0607598 0.00108347 -0.26" rpy="-1.5708 2.09359e-14 8.88178e-16" />
<geometry>
<mesh filename="package://hip_17.stl"/>
</geometry>
<material name="hip_17_material">
<color rgba="0.498039 0.498039 0.498039 1.0"/>
</material>
</visual>
<collision>
<origin xyz="0.0607598 0.00108347 -0.26" rpy="-1.5708 2.09359e-14 8.88178e-16" />
<geometry>
<mesh filename="package://hip_17.stl"/>
</geometry>
<material name="hip_17_material">
<color rgba="0.498039 0.498039 0.498039 1.0"/>
</material>
</collision>
<visual>
<origin xyz="0.0606778 -0.115907 -0.212439" rpy="-2.35619 3.45294e-14 -7.37995e-16" />
<geometry>
<mesh filename="package://hip_9.stl"/>
</geometry>
<material name="hip_9_material">
<color rgba="0.498039 0.498039 0.498039 1.0"/>
</material>
</visual>
<collision>
<origin xyz="0.0606778 -0.115907 -0.212439" rpy="-2.35619 3.45294e-14 -7.37995e-16" />
<geometry>
<mesh filename="package://hip_9.stl"/>
</geometry>
<material name="hip_9_material">
<color rgba="0.498039 0.498039 0.498039 1.0"/>
</material>
</collision>
<visual>
<origin xyz="0.0607938 0.00108347 -0.26" rpy="-1.5708 9.35987e-14 9.99201e-16" />
<geometry>
<mesh filename="package://hip_15.stl"/>
</geometry>
<material name="hip_15_material">
<color rgba="0.498039 0.498039 0.498039 1.0"/>
</material>
</visual>
<collision>
<origin xyz="0.0607938 0.00108347 -0.26" rpy="-1.5708 9.35987e-14 9.99201e-16" />
<geometry>
<mesh filename="package://hip_15.stl"/>
</geometry>
<material name="hip_15_material">
<color rgba="0.498039 0.498039 0.498039 1.0"/>
</material>
</collision>
<visual>
<origin xyz="0.0647938 0.00108347 -0.26" rpy="-1.5708 3.7477e-14 6.7682e-14" />
<geometry>
<mesh filename="package://hip_19.stl"/>
</geometry>
<material name="hip_19_material">
<color rgba="0.498039 0.498039 0.498039 1.0"/>
</material>
</visual>
<collision>
<origin xyz="0.0647938 0.00108347 -0.26" rpy="-1.5708 3.7477e-14 6.7682e-14" />
<geometry>
<mesh filename="package://hip_19.stl"/>
</geometry>
<material name="hip_19_material">
<color rgba="0.498039 0.498039 0.498039 1.0"/>
</material>
</collision>
<visual>
<origin xyz="0.0607938 0.00108347 -0.11" rpy="-1.5708 9.27848e-14 2.77556e-17" />
<geometry>
<mesh filename="package://motor9225v5_2.stl"/>
</geometry>
<material name="motor9225v5_2_material">
<color rgba="0.498039 0.498039 0.498039 1.0"/>
</material>
</visual>
<collision>
<origin xyz="0.0607938 0.00108347 -0.11" rpy="-1.5708 9.27848e-14 2.77556e-17" />
<geometry>
<mesh filename="package://motor9225v5_2.stl"/>
</geometry>
<material name="motor9225v5_2_material">
<color rgba="0.498039 0.498039 0.498039 1.0"/>
</material>
</collision>
<visual>
<origin xyz="0.0606938 0.00108347 -0.26" rpy="-1.5708 2.09166e-14 1.38778e-17" />
<geometry>
<mesh filename="package://hip_5.stl"/>
</geometry>
<material name="hip_5_material">
<color rgba="0.498039 0.498039 0.498039 1.0"/>
</material>
</visual>
<collision>
<origin xyz="0.0606938 0.00108347 -0.26" rpy="-1.5708 2.09166e-14 1.38778e-17" />
<geometry>
<mesh filename="package://hip_5.stl"/>
</geometry>
<material name="hip_5_material">
<color rgba="0.498039 0.498039 0.498039 1.0"/>
</material>
</collision>
<visual>
<origin xyz="0.0606938 0.00108347 -0.26" rpy="-1.5708 8.76247e-15 -4.02456e-16" />
<geometry>
<mesh filename="package://hip_2.stl"/>
</geometry>
<material name="hip_2_material">
<color rgba="0.498039 0.498039 0.498039 1.0"/>
</material>
</visual>
<collision>
<origin xyz="0.0606938 0.00108347 -0.26" rpy="-1.5708 8.76247e-15 -4.02456e-16" />
<geometry>
<mesh filename="package://hip_2.stl"/>
</geometry>
<material name="hip_2_material">
<color rgba="0.498039 0.498039 0.498039 1.0"/>
</material>
</collision>
<visual>
<origin xyz="0.0606938 0.00108347 -0.26" rpy="-1.5708 8.86529e-15 0" />
<geometry>
<mesh filename="package://hip_7.stl"/>
</geometry>
<material name="hip_7_material">
<color rgba="0.498039 0.498039 0.498039 1.0"/>
</material>
</visual>
<collision>
<origin xyz="0.0606938 0.00108347 -0.26" rpy="-1.5708 8.86529e-15 0" />
<geometry>
<mesh filename="package://hip_7.stl"/>
</geometry>
<material name="hip_7_material">
<color rgba="0.498039 0.498039 0.498039 1.0"/>
</material>
</collision>
<visual>
<origin xyz="0.0606938 0.00108347 -0.26" rpy="-1.5708 8.76247e-15 -4.16334e-16" />
<geometry>
<mesh filename="package://hip_1.stl"/>
</geometry>
<material name="hip_1_material">
<color rgba="0.498039 0.498039 0.498039 1.0"/>
</material>
</visual>
<collision>
<origin xyz="0.0606938 0.00108347 -0.26" rpy="-1.5708 8.76247e-15 -4.16334e-16" />
<geometry>
<mesh filename="package://hip_1.stl"/>
</geometry>
<material name="hip_1_material">
<color rgba="0.498039 0.498039 0.498039 1.0"/>
</material>
</collision>
<visual>
<origin xyz="0.0636938 0.00108347 -0.26" rpy="-1.5708 3.72051e-14 5.2401e-14" />
<geometry>
<mesh filename="package://hip_20.stl"/>
</geometry>
<material name="hip_20_material">
<color rgba="0.498039 0.498039 0.498039 1.0"/>
</material>
</visual>
<collision>
<origin xyz="0.0636938 0.00108347 -0.26" rpy="-1.5708 3.72051e-14 5.2401e-14" />
<geometry>
<mesh filename="package://hip_20.stl"/>
</geometry>
<material name="hip_20_material">
<color rgba="0.498039 0.498039 0.498039 1.0"/>
</material>
</collision>
<visual>
<origin xyz="0.0606938 0.00108347 -0.26" rpy="-1.5708 2.09166e-14 1.38778e-17" />
<geometry>
<mesh filename="package://hip_4.stl"/>
</geometry>
<material name="hip_4_material">
<color rgba="0.498039 0.498039 0.498039 1.0"/>
</material>
</visual>
<collision>
<origin xyz="0.0606938 0.00108347 -0.26" rpy="-1.5708 2.09166e-14 1.38778e-17" />
<geometry>
<mesh filename="package://hip_4.stl"/>
</geometry>
<material name="hip_4_material">
<color rgba="0.498039 0.498039 0.498039 1.0"/>
</material>
</collision>
<visual>
<origin xyz="0.0607598 0.00108347 -0.26" rpy="-1.5708 2.09166e-14 2.77556e-17" />
<geometry>
<mesh filename="package://hip_13.stl"/>
</geometry>
<material name="hip_13_material">
<color rgba="0.498039 0.498039 0.498039 1.0"/>
</material>
</visual>
<collision>
<origin xyz="0.0607598 0.00108347 -0.26" rpy="-1.5708 2.09166e-14 2.77556e-17" />
<geometry>
<mesh filename="package://hip_13.stl"/>
</geometry>
<material name="hip_13_material">
<color rgba="0.498039 0.498039 0.498039 1.0"/>
</material>
</collision>
<visual>
<origin xyz="0.0607938 0.00108347 -0.26" rpy="-1.5708 9.27848e-14 9.29812e-16" />
<geometry>
<mesh filename="package://hip_18.stl"/>
</geometry>
<material name="hip_18_material">
<color rgba="0.498039 0.498039 0.498039 1.0"/>
</material>
</visual>
<collision>
<origin xyz="0.0607938 0.00108347 -0.26" rpy="-1.5708 9.27848e-14 9.29812e-16" />
<geometry>
<mesh filename="package://hip_18.stl"/>
</geometry>
<material name="hip_18_material">
<color rgba="0.498039 0.498039 0.498039 1.0"/>
</material>
</collision>
<visual>
<origin xyz="0.0627938 0.00108347 -0.26" rpy="-1.5708 2.10583e-14 7.07767e-16" />
<geometry>
<mesh filename="package://hip_8.stl"/>
</geometry>
<material name="hip_8_material">
<color rgba="0.498039 0.498039 0.498039 1.0"/>
</material>
</visual>
<collision>
<origin xyz="0.0627938 0.00108347 -0.26" rpy="-1.5708 2.10583e-14 7.07767e-16" />
<geometry>
<mesh filename="package://hip_8.stl"/>
</geometry>
<material name="hip_8_material">
<color rgba="0.498039 0.498039 0.498039 1.0"/>
</material>
</collision>
<visual>
<origin xyz="0.0606938 0.00108347 -0.26" rpy="-1.5708 -1.39519e-15 1.38778e-17" />
<geometry>
<mesh filename="package://hip_12.stl"/>
</geometry>
<material name="hip_12_material">
<color rgba="0.498039 0.498039 0.498039 1.0"/>
</material>
</visual>
<collision>
<origin xyz="0.0606938 0.00108347 -0.26" rpy="-1.5708 -1.39519e-15 1.38778e-17" />
<geometry>
<mesh filename="package://hip_12.stl"/>
</geometry>
<material name="hip_12_material">
<color rgba="0.498039 0.498039 0.498039 1.0"/>
</material>
</collision>
<visual>
<origin xyz="0.0607598 0.00108347 -0.26" rpy="-1.5708 9.27848e-14 9.4369e-16" />
<geometry>
<mesh filename="package://hip_14.stl"/>
</geometry>
<material name="hip_14_material">
<color rgba="0.498039 0.498039 0.498039 1.0"/>
</material>
</visual>
<collision>
<origin xyz="0.0607598 0.00108347 -0.26" rpy="-1.5708 9.27848e-14 9.4369e-16" />
<geometry>
<mesh filename="package://hip_14.stl"/>
</geometry>
<material name="hip_14_material">
<color rgba="0.498039 0.498039 0.498039 1.0"/>
</material>
</collision>
<inertial>
<origin xyz="-0.0165949 -7.94503e-05 -0.13302" rpy="0 0 0"/>
<mass value="1.23" />
<inertia ixx="0.00898763" ixy="1.61607e-06"  ixz="1.67935e-05" iyy="0.00917046" iyz="-9.7706e-06" izz="0.00199049" />
</inertial>
</link>

<link name="upperleg">
<visual>
<origin xyz="-0.106049 0.027294 0.042084" rpy="1.8326 1.5708 0" />
<geometry>
<mesh filename="package://ams_2.stl"/>
</geometry>
<material name="ams_2_material">
<color rgba="0.917647 0.917647 0.917647 1.0"/>
</material>
</visual>
<collision>
<origin xyz="-0.106049 0.027294 0.042084" rpy="1.8326 1.5708 0" />
<geometry>
<mesh filename="package://ams_2.stl"/>
</geometry>
<material name="ams_2_material">
<color rgba="0.917647 0.917647 0.917647 1.0"/>
</material>
</collision>
<visual>
<origin xyz="-0.0766619 -0.0781945 0.042084" rpy="0.785398 1.5708 0" />
<geometry>
<mesh filename="package://ams_1.stl"/>
</geometry>
<material name="ams_1_material">
<color rgba="0.917647 0.917647 0.917647 1.0"/>
</material>
</visual>
<collision>
<origin xyz="-0.0766619 -0.0781945 0.042084" rpy="0.785398 1.5708 0" />
<geometry>
<mesh filename="package://ams_1.stl"/>
</geometry>
<material name="ams_1_material">
<color rgba="0.917647 0.917647 0.917647 1.0"/>
</material>
</collision>
<visual>
<origin xyz="0.115906 -0.117439 -0.032916" rpy="2.35619 1.5708 0" />
<geometry>
<mesh filename="package://upperleg_13.stl"/>
</geometry>
<material name="upperleg_13_material">
<color rgba="0.917647 0.917647 0.917647 1.0"/>
</material>
</visual>
<collision>
<origin xyz="0.115906 -0.117439 -0.032916" rpy="2.35619 1.5708 0" />
<geometry>
<mesh filename="package://upperleg_13.stl"/>
</geometry>
<material name="upperleg_13_material">
<color rgba="0.917647 0.917647 0.917647 1.0"/>
</material>
</collision>
<visual>
<origin xyz="0.165 -0.00108365 -0.032916" rpy="1.5708 1.5708 0" />
<geometry>
<mesh filename="package://upperleg_12.stl"/>
</geometry>
<material name="upperleg_12_material">
<color rgba="0.917647 0.917647 0.917647 1.0"/>
</material>
</visual>
<collision>
<origin xyz="0.165 -0.00108365 -0.032916" rpy="1.5708 1.5708 0" />
<geometry>
<mesh filename="package://upperleg_12.stl"/>
</geometry>
<material name="upperleg_12_material">
<color rgba="0.917647 0.917647 0.917647 1.0"/>
</material>
</collision>
<visual>
<origin xyz="0.165 -0.00108365 -0.032916" rpy="1.5708 1.5708 0" />
<geometry>
<mesh filename="package://upperleg_1.stl"/>
</geometry>
<material name="upperleg_1_material">
<color rgba="0.917647 0.917647 0.917647 1.0"/>
</material>
</visual>
<collision>
<origin xyz="0.165 -0.00108365 -0.032916" rpy="1.5708 1.5708 0" />
<geometry>
<mesh filename="package://upperleg_1.stl"/>
</geometry>
<material name="upperleg_1_material">
<color rgba="0.917647 0.917647 0.917647 1.0"/>
</material>
</collision>
<visual>
<origin xyz="0.164806 -0.00131537 -0.0323548" rpy="1.5708 1.5708 0" />
<geometry>
<mesh filename="package://upperleg_2.stl"/>
</geometry>
<material name="upperleg_2_material">
<color rgba="0.917647 0.917647 0.917647 1.0"/>
</material>
</visual>
<collision>
<origin xyz="0.164806 -0.00131537 -0.0323548" rpy="1.5708 1.5708 0" />
<geometry>
<mesh filename="package://upperleg_2.stl"/>
</geometry>
<material name="upperleg_2_material">
<color rgba="0.917647 0.917647 0.917647 1.0"/>
</material>
</collision>
<visual>
<origin xyz="0.165 -0.00108365 -0.032916" rpy="1.5708 1.5708 0" />
<geometry>
<mesh filename="package://upperleg_9.stl"/>
</geometry>
<material name="upperleg_9_material">
<color rgba="0.917647 0.917647 0.917647 1.0"/>
</material>
</visual>
<collision>
<origin xyz="0.165 -0.00108365 -0.032916" rpy="1.5708 1.5708 0" />
<geometry>
<mesh filename="package://upperleg_9.stl"/>
</geometry>
<material name="upperleg_9_material">
<color rgba="0.917647 0.917647 0.917647 1.0"/>
</material>
</collision>
<visual>
<origin xyz="0.165 -0.00108365 -0.032916" rpy="1.5708 1.5708 0" />
<geometry>
<mesh filename="package://upperleg_11.stl"/>
</geometry>
<material name="upperleg_11_material">
<color rgba="0.917647 0.917647 0.917647 1.0"/>
</material>
</visual>
<collision>
<origin xyz="0.165 -0.00108365 -0.032916" rpy="1.5708 1.5708 0" />
<geometry>
<mesh filename="package://upperleg_11.stl"/>
</geometry>
<material name="upperleg_11_material">
<color rgba="0.917647 0.917647 0.917647 1.0"/>
</material>
</collision>
<visual>
<origin xyz="0.165 -0.00108365 -0.033016" rpy="1.5708 1.5708 0" />
<geometry>
<mesh filename="package://upperleg_15.stl"/>
</geometry>
<material name="upperleg_15_material">
<color rgba="0.917647 0.917647 0.917647 1.0"/>
</material>
</visual>
<collision>
<origin xyz="0.165 -0.00108365 -0.033016" rpy="1.5708 1.5708 0" />
<geometry>
<mesh filename="package://upperleg_15.stl"/>
</geometry>
<material name="upperleg_15_material">
<color rgba="0.917647 0.917647 0.917647 1.0"/>
</material>
</collision>
<visual>
<origin xyz="0.165 -0.00108365 -0.032916" rpy="1.5708 1.5708 0" />
<geometry>
<mesh filename="package://upperleg_5.stl"/>
</geometry>
<material name="upperleg_5_material">
<color rgba="0.917647 0.917647 0.917647 1.0"/>
</material>
</visual>
<collision>
<origin xyz="0.165 -0.00108365 -0.032916" rpy="1.5708 1.5708 0" />
<geometry>
<mesh filename="package://upperleg_5.stl"/>
</geometry>
<material name="upperleg_5_material">
<color rgba="0.917647 0.917647 0.917647 1.0"/>
</material>
</collision>
<visual>
<origin xyz="0.165 -0.00108365 -0.032916" rpy="1.5708 1.5708 0" />
<geometry>
<mesh filename="package://upperleg_6.stl"/>
</geometry>
<material name="upperleg_6_material">
<color rgba="0.917647 0.917647 0.917647 1.0"/>
</material>
</visual>
<collision>
<origin xyz="0.165 -0.00108365 -0.032916" rpy="1.5708 1.5708 0" />
<geometry>
<mesh filename="package://upperleg_6.stl"/>
</geometry>
<material name="upperleg_6_material">
<color rgba="0.917647 0.917647 0.917647 1.0"/>
</material>
</collision>
<visual>
<origin xyz="0.165 -0.00108365 -0.032916" rpy="1.5708 1.5708 0" />
<geometry>
<mesh filename="package://upperleg_4.stl"/>
</geometry>
<material name="upperleg_4_material">
<color rgba="0.917647 0.917647 0.917647 1.0"/>
</material>
</visual>
<collision>
<origin xyz="0.165 -0.00108365 -0.032916" rpy="1.5708 1.5708 0" />
<geometry>
<mesh filename="package://upperleg_4.stl"/>
</geometry>
<material name="upperleg_4_material">
<color rgba="0.917647 0.917647 0.917647 1.0"/>
</material>
</collision>
<visual>
<origin xyz="0.165 -0.00108365 -0.032916" rpy="1.5708 1.5708 0" />
<geometry>
<mesh filename="package://upperleg_10.stl"/>
</geometry>
<material name="upperleg_10_material">
<color rgba="0.917647 0.917647 0.917647 1.0"/>
</material>
</visual>
<collision>
<origin xyz="0.165 -0.00108365 -0.032916" rpy="1.5708 1.5708 0" />
<geometry>
<mesh filename="package://upperleg_10.stl"/>
</geometry>
<material name="upperleg_10_material">
<color rgba="0.917647 0.917647 0.917647 1.0"/>
</material>
</collision>
<visual>
<origin xyz="0.00843847 0.0124486 -0.028916" rpy="0.523599 1.5708 0" />
<geometry>
<mesh filename="package://motor9225v5_1.stl"/>
</geometry>
<material name="motor9225v5_1_material">
<color rgba="0.917647 0.917647 0.917647 1.0"/>
</material>
</visual>
<collision>
<origin xyz="0.00843847 0.0124486 -0.028916" rpy="0.523599 1.5708 0" />
<geometry>
<mesh filename="package://motor9225v5_1.stl"/>
</geometry>
<material name="motor9225v5_1_material">
<color rgba="0.917647 0.917647 0.917647 1.0"/>
</material>
</collision>
<visual>
<origin xyz="0.165 -0.00108365 -0.032916" rpy="1.5708 1.5708 0" />
<geometry>
<mesh filename="package://upperleg_7.stl"/>
</geometry>
<material name="upperleg_7_material">
<color rgba="0.917647 0.917647 0.917647 1.0"/>
</material>
</visual>
<collision>
<origin xyz="0.165 -0.00108365 -0.032916" rpy="1.5708 1.5708 0" />
<geometry>
<mesh filename="package://upperleg_7.stl"/>
</geometry>
<material name="upperleg_7_material">
<color rgba="0.917647 0.917647 0.917647 1.0"/>
</material>
</collision>
<visual>
<origin xyz="0.165 -0.00108365 -0.032916" rpy="1.5708 1.5708 0" />
<geometry>
<mesh filename="package://upperleg_8.stl"/>
</geometry>
<material name="upperleg_8_material">
<color rgba="0.917647 0.917647 0.917647 1.0"/>
</material>
</visual>
<collision>
<origin xyz="0.165 -0.00108365 -0.032916" rpy="1.5708 1.5708 0" />
<geometry>
<mesh filename="package://upperleg_8.stl"/>
</geometry>
<material name="upperleg_8_material">
<color rgba="0.917647 0.917647 0.917647 1.0"/>
</material>
</collision>
<visual>
<origin xyz="0.165 -0.00108365 -0.032816" rpy="1.5708 1.5708 0" />
<geometry>
<mesh filename="package://upperleg_14.stl"/>
</geometry>
<material name="upperleg_14_material">
<color rgba="0.917647 0.917647 0.917647 1.0"/>
</material>
</visual>
<collision>
<origin xyz="0.165 -0.00108365 -0.032816" rpy="1.5708 1.5708 0" />
<geometry>
<mesh filename="package://upperleg_14.stl"/>
</geometry>
<material name="upperleg_14_material">
<color rgba="0.917647 0.917647 0.917647 1.0"/>
</material>
</collision>
<visual>
<origin xyz="0.165 -0.00108365 -0.032916" rpy="1.5708 1.5708 0" />
<geometry>
<mesh filename="package://upperleg_3.stl"/>
</geometry>
<material name="upperleg_3_material">
<color rgba="0.917647 0.917647 0.917647 1.0"/>
</material>
</visual>
<collision>
<origin xyz="0.165 -0.00108365 -0.032916" rpy="1.5708 1.5708 0" />
<geometry>
<mesh filename="package://upperleg_3.stl"/>
</geometry>
<material name="upperleg_3_material">
<color rgba="0.917647 0.917647 0.917647 1.0"/>
</material>
</collision>
<inertial>
<origin xyz="-0.000592499 0.0567057 -0.043972" rpy="0 0 0"/>
<mass value="0.97" />
<inertia ixx="0.00309778" ixy="3.64215e-05"  ixz="2.28223e-05" iyy="0.00465531" iyz="-0.000182553" izz="0.00543222" />
</inertial>
</link>

<link name="lowerleg">
<visual>
<origin xyz="0.165 0.201084 -0.0325" rpy="-1.5708 -1.5708 0" />
<geometry>
<mesh filename="package://lowerleg_2.stl"/>
</geometry>
<material name="lowerleg_2_material">
<color rgba="0.615686 0.811765 0.929412 1.0"/>
</material>
</visual>
<collision>
<origin xyz="0.165 0.201084 -0.0325" rpy="-1.5708 -1.5708 0" />
<geometry>
<mesh filename="package://lowerleg_2.stl"/>
</geometry>
<material name="lowerleg_2_material">
<color rgba="0.615686 0.811765 0.929412 1.0"/>
</material>
</collision>
<visual>
<origin xyz="0.165 0.201114 -0.03229" rpy="-1.5708 -1.5708 0" />
<geometry>
<mesh filename="package://lowerleg_3.stl"/>
</geometry>
<material name="lowerleg_3_material">
<color rgba="0.615686 0.811765 0.929412 1.0"/>
</material>
</visual>
<collision>
<origin xyz="0.165 0.201114 -0.03229" rpy="-1.5708 -1.5708 0" />
<geometry>
<mesh filename="package://lowerleg_3.stl"/>
</geometry>
<material name="lowerleg_3_material">
<color rgba="0.615686 0.811765 0.929412 1.0"/>
</material>
</collision>
<visual>
<origin xyz="0.165 0.201084 -0.0325" rpy="-1.5708 -1.5708 0" />
<geometry>
<mesh filename="package://foot.stl"/>
</geometry>
<material name="foot_material">
<color rgba="0.815686 0.00392157 0.00392157 1.0"/>
</material>
</visual>
<collision>
<origin xyz="0.165 0.201084 -0.0325" rpy="-1.5708 -1.5708 0" />
<geometry>
<mesh filename="package://foot.stl"/>
</geometry>
<material name="foot_material">
<color rgba="0.815686 0.00392157 0.00392157 1.0"/>
</material>
</collision>
<visual>
<origin xyz="0.165 0.201084 -0.0325" rpy="-1.5708 -1.5708 0" />
<geometry>
<mesh filename="package://lowerleg_1.stl"/>
</geometry>
<material name="lowerleg_1_material">
<color rgba="0.615686 0.811765 0.929412 1.0"/>
</material>
</visual>
<collision>
<origin xyz="0.165 0.201084 -0.0325" rpy="-1.5708 -1.5708 0" />
<geometry>
<mesh filename="package://lowerleg_1.stl"/>
</geometry>
<material name="lowerleg_1_material">
<color rgba="0.615686 0.811765 0.929412 1.0"/>
</material>
</collision>
<inertial>
<origin xyz="2.76478e-06 -0.0634662 -0.0415243" rpy="0 0 0"/>
<mass value="0.34" />
<inertia ixx="0.0024225" ixy="-3.78677e-06"  ixz="5.33358e-08" iyy="0.00107662" iyz="-0.000776024" izz="0.00248712" />
</inertial>
</link>

<link name="foot_fl">
<inertial>
<origin xyz="0 0 0" rpy="0 0 0" />
<mass value="1e-9" />
<inertia ixx="0" ixy="0" ixz="0" iyy="0" iyz="0" izz="0" />
</inertial>
</link>
<joint name="foot_fl_frame" type="fixed">
<origin xyz="1.44661e-05 -0.195916 -0.0978296" rpy="-1.5708 -1.5708 0" />
<parent link="lowerleg" />
<child link="foot_fl" />
<axis xyz="0 0 0"/>
</joint>

<joint name="ankle_fl" type="revolute">
<origin xyz="-4.27436e-15 0.2 -0.065516" rpy="-3.14159 -4.05626e-17 -2.77556e-16" />
<parent link="upperleg" />
<child link="lowerleg" />
<axis xyz="0 0 1"/>
<limit effort="1" velocity="20" lower="-2.35619" upper="2.35619"/>
<joint_properties friction="0.0"/>
</joint>

<joint name="knee_fl" type="revolute">
<origin xyz="0.0319938 -1.83141e-07 -0.095" rpy="-3.14159 1.5708 0" />
<parent link="hip" />
<child link="upperleg" />
<axis xyz="0 0 1"/>
<limit effort="1" velocity="20" lower="-0.872665" upper="0.698132"/>
<joint_properties friction="0.0"/>
</joint>

<joint name="hip_fl" type="revolute">
<origin xyz="0.123746 -0.360089 0.0733429" rpy="1.5708 -4.4944e-14 6.38027e-10" />
<parent link="body" />
<child link="hip" />
<axis xyz="0 0 1"/>
<limit effort="1" velocity="20" lower="-0.523599" upper="1.39626"/>
<joint_properties friction="0.0"/>
</joint>

<link name="mirrorhip">
<visual>
<origin xyz="0.0607278 0.00108347 -0.0345" rpy="1.5708 -5.0157e-14 -5.55112e-16" />
<geometry>
<mesh filename="package://hipm_15.stl"/>
</geometry>
<material name="hipm_15_material">
<color rgba="0.498039 0.498039 0.498039 1.0"/>
</material>
</visual>
<collision>
<origin xyz="0.0607278 0.00108347 -0.0345" rpy="1.5708 -5.0157e-14 -5.55112e-16" />
<geometry>
<mesh filename="package://hipm_15.stl"/>
</geometry>
<material name="hipm_15_material">
<color rgba="0.498039 0.498039 0.498039 1.0"/>
</material>
</collision>
<visual>
<origin xyz="0.0606938 0.00108347 -0.034" rpy="1.5708 3.48953e-14 4.33264e-30" />
<geometry>
<mesh filename="package://hipm_5.stl"/>
</geometry>
<material name="hipm_5_material">
<color rgba="0.498039 0.498039 0.498039 1.0"/>
</material>
</visual>
<collision>
<origin xyz="0.0606938 0.00108347 -0.034" rpy="1.5708 3.48953e-14 4.33264e-30" />
<geometry>
<mesh filename="package://hipm_5.stl"/>
</geometry>
<material name="hipm_5_material">
<color rgba="0.498039 0.498039 0.498039 1.0"/>
</material>
</collision>
<visual>
<origin xyz="0.0607278 0.00108347 -0.0345" rpy="1.5708 2.07748e-14 -6.10623e-16" />
<geometry>
<mesh filename="package://hipm_11.stl"/>
</geometry>
<material name="hipm_11_material">
<color rgba="0.498039 0.498039 0.498039 1.0"/>
</material>
</visual>
<collision>
<origin xyz="0.0607278 0.00108347 -0.0345" rpy="1.5708 2.07748e-14 -6.10623e-16" />
<geometry>
<mesh filename="package://hipm_11.stl"/>
</geometry>
<material name="hipm_11_material">
<color rgba="0.498039 0.498039 0.498039 1.0"/>
</material>
</collision>
<visual>
<origin xyz="0.0606938 0.117439 -0.0835936" rpy="0.785398 2.66641e-14 -1.3804e-14" />
<geometry>
<mesh filename="package://hipm_16.stl"/>
</geometry>
<material name="hipm_16_material">
<color rgba="0.498039 0.498039 0.498039 1.0"/>
</material>
</visual>
<collision>
<origin xyz="0.0606938 0.117439 -0.0835936" rpy="0.785398 2.66641e-14 -1.3804e-14" />
<geometry>
<mesh filename="package://hipm_16.stl"/>
</geometry>
<material name="hipm_16_material">
<color rgba="0.498039 0.498039 0.498039 1.0"/>
</material>
</collision>
<visual>
<origin xyz="0.0606938 0.00108347 -0.0345" rpy="1.5708 4.96475e-14 5.55111e-17" />
<geometry>
<mesh filename="package://hipm_9.stl"/>
</geometry>
<material name="hipm_9_material">
<color rgba="0.498039 0.498039 0.498039 1.0"/>
</material>
</visual>
<collision>
<origin xyz="0.0606938 0.00108347 -0.0345" rpy="1.5708 4.96475e-14 5.55111e-17" />
<geometry>
<mesh filename="package://hipm_9.stl"/>
</geometry>
<material name="hipm_9_material">
<color rgba="0.498039 0.498039 0.498039 1.0"/>
</material>
</collision>
<visual>
<origin xyz="0.0606938 0.00108347 -0.0345" rpy="1.5708 2.08973e-14 9.4369e-16" />
<geometry>
<mesh filename="package://hipm_17.stl"/>
</geometry>
<material name="hipm_17_material">
<color rgba="0.498039 0.498039 0.498039 1.0"/>
</material>
</visual>
<collision>
<origin xyz="0.0606938 0.00108347 -0.0345" rpy="1.5708 2.08973e-14 9.4369e-16" />
<geometry>
<mesh filename="package://hipm_17.stl"/>
</geometry>
<material name="hipm_17_material">
<color rgba="0.498039 0.498039 0.498039 1.0"/>
</material>
</collision>
<visual>
<origin xyz="0.0606118 0.117439 -0.0835936" rpy="0.785398 2.13478e-14 1.25858e-14" />
<geometry>
<mesh filename="package://hipm_12.stl"/>
</geometry>
<material name="hipm_12_material">
<color rgba="0.498039 0.498039 0.498039 1.0"/>
</material>
</visual>
<collision>
<origin xyz="0.0606118 0.117439 -0.0835936" rpy="0.785398 2.13478e-14 1.25858e-14" />
<geometry>
<mesh filename="package://hipm_12.stl"/>
</geometry>
<material name="hipm_12_material">
<color rgba="0.498039 0.498039 0.498039 1.0"/>
</material>
</collision>
<visual>
<origin xyz="0.0606938 0.00108347 -0.0345" rpy="1.5708 2.09166e-14 -5.52828e-24" />
<geometry>
<mesh filename="package://hipm_10.stl"/>
</geometry>
<material name="hipm_10_material">
<color rgba="0.498039 0.498039 0.498039 1.0"/>
</material>
</visual>
<collision>
<origin xyz="0.0606938 0.00108347 -0.0345" rpy="1.5708 2.09166e-14 -5.52828e-24" />
<geometry>
<mesh filename="package://hipm_10.stl"/>
</geometry>
<material name="hipm_10_material">
<color rgba="0.498039 0.498039 0.498039 1.0"/>
</material>
</collision>
<visual>
<origin xyz="0.0607278 0.00108347 -0.0345" rpy="1.5708 -5.09516e-14 -5.55112e-16" />
<geometry>
<mesh filename="package://hipm_18.stl"/>
</geometry>
<material name="hipm_18_material">
<color rgba="0.498039 0.498039 0.498039 1.0"/>
</material>
</visual>
<collision>
<origin xyz="0.0607278 0.00108347 -0.0345" rpy="1.5708 -5.09516e-14 -5.55112e-16" />
<geometry>
<mesh filename="package://hipm_18.stl"/>
</geometry>
<material name="hipm_18_material">
<color rgba="0.498039 0.498039 0.498039 1.0"/>
</material>
</collision>
<visual>
<origin xyz="0.0647278 0.00108347 -0.0345" rpy="1.5708 4.35623e-15 6.62803e-14" />
<geometry>
<mesh filename="package://hipm_19.stl"/>
</geometry>
<material name="hipm_19_material">
<color rgba="0.498039 0.498039 0.498039 1.0"/>
</material>
</visual>
<collision>
<origin xyz="0.0647278 0.00108347 -0.0345" rpy="1.5708 4.35623e-15 6.62803e-14" />
<geometry>
<mesh filename="package://hipm_19.stl"/>
</geometry>
<material name="hipm_19_material">
<color rgba="0.498039 0.498039 0.498039 1.0"/>
</material>
</collision>
<visual>
<origin xyz="0.0636278 0.00108347 -0.3645" rpy="-1.5708 3.62662e-14 5.19583e-14" />
<geometry>
<mesh filename="package://hip_20.stl"/>
</geometry>
<material name="hip_20_material">
<color rgba="0.498039 0.498039 0.498039 1.0"/>
</material>
</visual>
<collision>
<origin xyz="0.0636278 0.00108347 -0.3645" rpy="-1.5708 3.62662e-14 5.19583e-14" />
<geometry>
<mesh filename="package://hip_20.stl"/>
</geometry>
<material name="hip_20_material">
<color rgba="0.498039 0.498039 0.498039 1.0"/>
</material>
</collision>
<visual>
<origin xyz="0.0606938 0.0011249 -0.0339507" rpy="1.5708 3.48178e-14 4.996e-16" />
<geometry>
<mesh filename="package://hipm_2.stl"/>
</geometry>
<material name="hipm_2_material">
<color rgba="0.498039 0.498039 0.498039 1.0"/>
</material>
</visual>
<collision>
<origin xyz="0.0606938 0.0011249 -0.0339507" rpy="1.5708 3.48178e-14 4.996e-16" />
<geometry>
<mesh filename="package://hipm_2.stl"/>
</geometry>
<material name="hipm_2_material">
<color rgba="0.498039 0.498039 0.498039 1.0"/>
</material>
</collision>
<visual>
<origin xyz="0.0606938 0.0011249 -0.0339507" rpy="1.5708 3.48178e-14 5.55112e-16" />
<geometry>
<mesh filename="package://hipm_3.stl"/>
</geometry>
<material name="hipm_3_material">
<color rgba="0.498039 0.498039 0.498039 1.0"/>
</material>
</visual>
<collision>
<origin xyz="0.0606938 0.0011249 -0.0339507" rpy="1.5708 3.48178e-14 5.55112e-16" />
<geometry>
<mesh filename="package://hipm_3.stl"/>
</geometry>
<material name="hipm_3_material">
<color rgba="0.498039 0.498039 0.498039 1.0"/>
</material>
</collision>
<visual>
<origin xyz="0.0606938 0.00108347 -0.0345" rpy="1.5708 -5.09516e-14 9.4369e-16" />
<geometry>
<mesh filename="package://hipm_14.stl"/>
</geometry>
<material name="hipm_14_material">
<color rgba="0.498039 0.498039 0.498039 1.0"/>
</material>
</visual>
<collision>
<origin xyz="0.0606938 0.00108347 -0.0345" rpy="1.5708 -5.09516e-14 9.4369e-16" />
<geometry>
<mesh filename="package://hipm_14.stl"/>
</geometry>
<material name="hipm_14_material">
<color rgba="0.498039 0.498039 0.498039 1.0"/>
</material>
</collision>
<visual>
<origin xyz="0.0606938 0.00108347 -0.0345" rpy="1.5708 1.57865e-14 -1.86435e-23" />
<geometry>
<mesh filename="package://hipm_8.stl"/>
</geometry>
<material name="hipm_8_material">
<color rgba="0.498039 0.498039 0.498039 1.0"/>
</material>
</visual>
<collision>
<origin xyz="0.0606938 0.00108347 -0.0345" rpy="1.5708 1.57865e-14 -1.86435e-23" />
<geometry>
<mesh filename="package://hipm_8.stl"/>
</geometry>
<material name="hipm_8_material">
<color rgba="0.498039 0.498039 0.498039 1.0"/>
</material>
</collision>
<visual>
<origin xyz="0.0607278 0.00108347 -0.1845" rpy="1.5708 -5.09516e-14 -1.33227e-15" />
<geometry>
<mesh filename="package://motor9225v5_3.stl"/>
</geometry>
<material name="motor9225v5_3_material">
<color rgba="0.498039 0.498039 0.498039 1.0"/>
</material>
</visual>
<collision>
<origin xyz="0.0607278 0.00108347 -0.1845" rpy="1.5708 -5.09516e-14 -1.33227e-15" />
<geometry>
<mesh filename="package://motor9225v5_3.stl"/>
</geometry>
<material name="motor9225v5_3_material">
<color rgba="0.498039 0.498039 0.498039 1.0"/>
</material>
</collision>
<visual>
<origin xyz="0.0606278 0.00108347 -0.0345" rpy="1.5708 2.09166e-14 -4.44089e-16" />
<geometry>
<mesh filename="package://hipm_13.stl"/>
</geometry>
<material name="hipm_13_material">
<color rgba="0.498039 0.498039 0.498039 1.0"/>
</material>
</visual>
<collision>
<origin xyz="0.0606278 0.00108347 -0.0345" rpy="1.5708 2.09166e-14 -4.44089e-16" />
<geometry>
<mesh filename="package://hipm_13.stl"/>
</geometry>
<material name="hipm_13_material">
<color rgba="0.498039 0.498039 0.498039 1.0"/>
</material>
</collision>
<visual>
<origin xyz="0.0606938 0.0011249 -0.0339507" rpy="1.5708 3.48178e-14 5.55112e-16" />
<geometry>
<mesh filename="package://hipm_1.stl"/>
</geometry>
<material name="hipm_1_material">
<color rgba="0.498039 0.498039 0.498039 1.0"/>
</material>
</visual>
<collision>
<origin xyz="0.0606938 0.0011249 -0.0339507" rpy="1.5708 3.48178e-14 5.55112e-16" />
<geometry>
<mesh filename="package://hipm_1.stl"/>
</geometry>
<material name="hipm_1_material">
<color rgba="0.498039 0.498039 0.498039 1.0"/>
</material>
</collision>
<visual>
<origin xyz="0.0606278 0.00108347 -0.0345" rpy="1.5708 2.2844e-14 -6.10623e-16" />
<geometry>
<mesh filename="package://hipm_6.stl"/>
</geometry>
<material name="hipm_6_material">
<color rgba="0.498039 0.498039 0.498039 1.0"/>
</material>
</visual>
<collision>
<origin xyz="0.0606278 0.00108347 -0.0345" rpy="1.5708 2.2844e-14 -6.10623e-16" />
<geometry>
<mesh filename="package://hipm_6.stl"/>
</geometry>
<material name="hipm_6_material">
<color rgba="0.498039 0.498039 0.498039 1.0"/>
</material>
</collision>
<visual>
<origin xyz="0.0606278 0.00108347 -0.0345" rpy="1.5708 2.28311e-14 -3.90789e-24" />
<geometry>
<mesh filename="package://hipm_4.stl"/>
</geometry>
<material name="hipm_4_material">
<color rgba="0.498039 0.498039 0.498039 1.0"/>
</material>
</visual>
<collision>
<origin xyz="0.0606278 0.00108347 -0.0345" rpy="1.5708 2.28311e-14 -3.90789e-24" />
<geometry>
<mesh filename="package://hipm_4.stl"/>
</geometry>
<material name="hipm_4_material">
<color rgba="0.498039 0.498039 0.498039 1.0"/>
</material>
</collision>
<visual>
<origin xyz="0.0300118 -1.83141e-07 -0.075" rpy="1.5708 2.42113e-15 1.5708" />
<geometry>
<mesh filename="package://ams_6.stl"/>
</geometry>
<material name="ams_6_material">
<color rgba="0.498039 0.498039 0.498039 1.0"/>
</material>
</visual>
<collision>
<origin xyz="0.0300118 -1.83141e-07 -0.075" rpy="1.5708 2.42113e-15 1.5708" />
<geometry>
<mesh filename="package://ams_6.stl"/>
</geometry>
<material name="ams_6_material">
<color rgba="0.498039 0.498039 0.498039 1.0"/>
</material>
</collision>
<visual>
<origin xyz="0.0606938 0.00108347 -0.0345" rpy="1.5708 3.94256e-14 -1.37482e-23" />
<geometry>
<mesh filename="package://hipm_7.stl"/>
</geometry>
<material name="hipm_7_material">
<color rgba="0.498039 0.498039 0.498039 1.0"/>
</material>
</visual>
<collision>
<origin xyz="0.0606938 0.00108347 -0.0345" rpy="1.5708 3.94256e-14 -1.37482e-23" />
<geometry>
<mesh filename="package://hipm_7.stl"/>
</geometry>
<material name="hipm_7_material">
<color rgba="0.498039 0.498039 0.498039 1.0"/>
</material>
</collision>
<visual>
<origin xyz="0.0299278 -1.83141e-07 -0.075" rpy="1.5708 2.42113e-15 1.5708" />
<geometry>
<mesh filename="package://ams_5.stl"/>
</geometry>
<material name="ams_5_material">
<color rgba="0.498039 0.498039 0.498039 1.0"/>
</material>
</visual>
<collision>
<origin xyz="0.0299278 -1.83141e-07 -0.075" rpy="1.5708 2.42113e-15 1.5708" />
<geometry>
<mesh filename="package://ams_5.stl"/>
</geometry>
<material name="ams_5_material">
<color rgba="0.498039 0.498039 0.498039 1.0"/>
</material>
</collision>
<inertial>
<origin xyz="-0.0166451 -7.90316e-05 -0.135122" rpy="0 0 0"/>
<mass value="1.23081" />
<inertia ixx="0.00905897" ixy="1.5955e-06"  ixz="-0.000220206" iyy="0.00924287" iyz="7.16432e-06" izz="0.00199167" />
</inertial>
</link>

<link name="upperleg_2">
<visual>
<origin xyz="0.164806 -0.00131537 -0.0323548" rpy="1.5708 1.5708 0" />
<geometry>
<mesh filename="package://upperleg_2.stl"/>
</geometry>
<material name="upperleg_2_material">
<color rgba="0.917647 0.917647 0.917647 1.0"/>
</material>
</visual>
<collision>
<origin xyz="0.164806 -0.00131537 -0.0323548" rpy="1.5708 1.5708 0" />
<geometry>
<mesh filename="package://upperleg_2.stl"/>
</geometry>
<material name="upperleg_2_material">
<color rgba="0.917647 0.917647 0.917647 1.0"/>
</material>
</collision>
<visual>
<origin xyz="0.165 -0.00108365 -0.033016" rpy="1.5708 1.5708 0" />
<geometry>
<mesh filename="package://upperleg_15.stl"/>
</geometry>
<material name="upperleg_15_material">
<color rgba="0.917647 0.917647 0.917647 1.0"/>
</material>
</visual>
<collision>
<origin xyz="0.165 -0.00108365 -0.033016" rpy="1.5708 1.5708 0" />
<geometry>
<mesh filename="package://upperleg_15.stl"/>
</geometry>
<material name="upperleg_15_material">
<color rgba="0.917647 0.917647 0.917647 1.0"/>
</material>
</collision>
<visual>
<origin xyz="0.165 -0.00108365 -0.032916" rpy="1.5708 1.5708 0" />
<geometry>
<mesh filename="package://upperleg_1.stl"/>
</geometry>
<material name="upperleg_1_material">
<color rgba="0.917647 0.917647 0.917647 1.0"/>
</material>
</visual>
<collision>
<origin xyz="0.165 -0.00108365 -0.032916" rpy="1.5708 1.5708 0" />
<geometry>
<mesh filename="package://upperleg_1.stl"/>
</geometry>
<material name="upperleg_1_material">
<color rgba="0.917647 0.917647 0.917647 1.0"/>
</material>
</collision>
<visual>
<origin xyz="0.165 -0.00108365 -0.032916" rpy="1.5708 1.5708 0" />
<geometry>
<mesh filename="package://upperleg_5.stl"/>
</geometry>
<material name="upperleg_5_material">
<color rgba="0.917647 0.917647 0.917647 1.0"/>
</material>
</visual>
<collision>
<origin xyz="0.165 -0.00108365 -0.032916" rpy="1.5708 1.5708 0" />
<geometry>
<mesh filename="package://upperleg_5.stl"/>
</geometry>
<material name="upperleg_5_material">
<color rgba="0.917647 0.917647 0.917647 1.0"/>
</material>
</collision>
<visual>
<origin xyz="0.165 -0.00108365 -0.032916" rpy="1.5708 1.5708 0" />
<geometry>
<mesh filename="package://upperleg_12.stl"/>
</geometry>
<material name="upperleg_12_material">
<color rgba="0.917647 0.917647 0.917647 1.0"/>
</material>
</visual>
<collision>
<origin xyz="0.165 -0.00108365 -0.032916" rpy="1.5708 1.5708 0" />
<geometry>
<mesh filename="package://upperleg_12.stl"/>
</geometry>
<material name="upperleg_12_material">
<color rgba="0.917647 0.917647 0.917647 1.0"/>
</material>
</collision>
<visual>
<origin xyz="-0.106049 0.027294 0.042084" rpy="1.8326 1.5708 0" />
<geometry>
<mesh filename="package://ams_2.stl"/>
</geometry>
<material name="ams_2_material">
<color rgba="0.917647 0.917647 0.917647 1.0"/>
</material>
</visual>
<collision>
<origin xyz="-0.106049 0.027294 0.042084" rpy="1.8326 1.5708 0" />
<geometry>
<mesh filename="package://ams_2.stl"/>
</geometry>
<material name="ams_2_material">
<color rgba="0.917647 0.917647 0.917647 1.0"/>
</material>
</collision>
<visual>
<origin xyz="0.165 -0.00108365 -0.032916" rpy="1.5708 1.5708 0" />
<geometry>
<mesh filename="package://upperleg_8.stl"/>
</geometry>
<material name="upperleg_8_material">
<color rgba="0.917647 0.917647 0.917647 1.0"/>
</material>
</visual>
<collision>
<origin xyz="0.165 -0.00108365 -0.032916" rpy="1.5708 1.5708 0" />
<geometry>
<mesh filename="package://upperleg_8.stl"/>
</geometry>
<material name="upperleg_8_material">
<color rgba="0.917647 0.917647 0.917647 1.0"/>
</material>
</collision>
<visual>
<origin xyz="-0.0766619 -0.0781945 0.042084" rpy="0.785398 1.5708 0" />
<geometry>
<mesh filename="package://ams_1.stl"/>
</geometry>
<material name="ams_1_material">
<color rgba="0.917647 0.917647 0.917647 1.0"/>
</material>
</visual>
<collision>
<origin xyz="-0.0766619 -0.0781945 0.042084" rpy="0.785398 1.5708 0" />
<geometry>
<mesh filename="package://ams_1.stl"/>
</geometry>
<material name="ams_1_material">
<color rgba="0.917647 0.917647 0.917647 1.0"/>
</material>
</collision>
<visual>
<origin xyz="0.00843847 0.0124486 -0.028916" rpy="0.523599 1.5708 0" />
<geometry>
<mesh filename="package://motor9225v5_1.stl"/>
</geometry>
<material name="motor9225v5_1_material">
<color rgba="0.917647 0.917647 0.917647 1.0"/>
</material>
</visual>
<collision>
<origin xyz="0.00843847 0.0124486 -0.028916" rpy="0.523599 1.5708 0" />
<geometry>
<mesh filename="package://motor9225v5_1.stl"/>
</geometry>
<material name="motor9225v5_1_material">
<color rgba="0.917647 0.917647 0.917647 1.0"/>
</material>
</collision>
<visual>
<origin xyz="0.165 -0.00108365 -0.032916" rpy="1.5708 1.5708 0" />
<geometry>
<mesh filename="package://upperleg_3.stl"/>
</geometry>
<material name="upperleg_3_material">
<color rgba="0.917647 0.917647 0.917647 1.0"/>
</material>
</visual>
<collision>
<origin xyz="0.165 -0.00108365 -0.032916" rpy="1.5708 1.5708 0" />
<geometry>
<mesh filename="package://upperleg_3.stl"/>
</geometry>
<material name="upperleg_3_material">
<color rgba="0.917647 0.917647 0.917647 1.0"/>
</material>
</collision>
<visual>
<origin xyz="0.165 -0.00108365 -0.032916" rpy="1.5708 1.5708 0" />
<geometry>
<mesh filename="package://upperleg_4.stl"/>
</geometry>
<material name="upperleg_4_material">
<color rgba="0.917647 0.917647 0.917647 1.0"/>
</material>
</visual>
<collision>
<origin xyz="0.165 -0.00108365 -0.032916" rpy="1.5708 1.5708 0" />
<geometry>
<mesh filename="package://upperleg_4.stl"/>
</geometry>
<material name="upperleg_4_material">
<color rgba="0.917647 0.917647 0.917647 1.0"/>
</material>
</collision>
<visual>
<origin xyz="0.115906 -0.117439 -0.032916" rpy="2.35619 1.5708 0" />
<geometry>
<mesh filename="package://upperleg_13.stl"/>
</geometry>
<material name="upperleg_13_material">
<color rgba="0.917647 0.917647 0.917647 1.0"/>
</material>
</visual>
<collision>
<origin xyz="0.115906 -0.117439 -0.032916" rpy="2.35619 1.5708 0" />
<geometry>
<mesh filename="package://upperleg_13.stl"/>
</geometry>
<material name="upperleg_13_material">
<color rgba="0.917647 0.917647 0.917647 1.0"/>
</material>
</collision>
<visual>
<origin xyz="0.165 -0.00108365 -0.032816" rpy="1.5708 1.5708 0" />
<geometry>
<mesh filename="package://upperleg_14.stl"/>
</geometry>
<material name="upperleg_14_material">
<color rgba="0.917647 0.917647 0.917647 1.0"/>
</material>
</visual>
<collision>
<origin xyz="0.165 -0.00108365 -0.032816" rpy="1.5708 1.5708 0" />
<geometry>
<mesh filename="package://upperleg_14.stl"/>
</geometry>
<material name="upperleg_14_material">
<color rgba="0.917647 0.917647 0.917647 1.0"/>
</material>
</collision>
<visual>
<origin xyz="0.165 -0.00108365 -0.032916" rpy="1.5708 1.5708 0" />
<geometry>
<mesh filename="package://upperleg_6.stl"/>
</geometry>
<material name="upperleg_6_material">
<color rgba="0.917647 0.917647 0.917647 1.0"/>
</material>
</visual>
<collision>
<origin xyz="0.165 -0.00108365 -0.032916" rpy="1.5708 1.5708 0" />
<geometry>
<mesh filename="package://upperleg_6.stl"/>
</geometry>
<material name="upperleg_6_material">
<color rgba="0.917647 0.917647 0.917647 1.0"/>
</material>
</collision>
<visual>
<origin xyz="0.165 -0.00108365 -0.032916" rpy="1.5708 1.5708 0" />
<geometry>
<mesh filename="package://upperleg_10.stl"/>
</geometry>
<material name="upperleg_10_material">
<color rgba="0.917647 0.917647 0.917647 1.0"/>
</material>
</visual>
<collision>
<origin xyz="0.165 -0.00108365 -0.032916" rpy="1.5708 1.5708 0" />
<geometry>
<mesh filename="package://upperleg_10.stl"/>
</geometry>
<material name="upperleg_10_material">
<color rgba="0.917647 0.917647 0.917647 1.0"/>
</material>
</collision>
<visual>
<origin xyz="0.165 -0.00108365 -0.032916" rpy="1.5708 1.5708 0" />
<geometry>
<mesh filename="package://upperleg_7.stl"/>
</geometry>
<material name="upperleg_7_material">
<color rgba="0.917647 0.917647 0.917647 1.0"/>
</material>
</visual>
<collision>
<origin xyz="0.165 -0.00108365 -0.032916" rpy="1.5708 1.5708 0" />
<geometry>
<mesh filename="package://upperleg_7.stl"/>
</geometry>
<material name="upperleg_7_material">
<color rgba="0.917647 0.917647 0.917647 1.0"/>
</material>
</collision>
<visual>
<origin xyz="0.165 -0.00108365 -0.032916" rpy="1.5708 1.5708 0" />
<geometry>
<mesh filename="package://upperleg_11.stl"/>
</geometry>
<material name="upperleg_11_material">
<color rgba="0.917647 0.917647 0.917647 1.0"/>
</material>
</visual>
<collision>
<origin xyz="0.165 -0.00108365 -0.032916" rpy="1.5708 1.5708 0" />
<geometry>
<mesh filename="package://upperleg_11.stl"/>
</geometry>
<material name="upperleg_11_material">
<color rgba="0.917647 0.917647 0.917647 1.0"/>
</material>
</collision>
<visual>
<origin xyz="0.165 -0.00108365 -0.032916" rpy="1.5708 1.5708 0" />
<geometry>
<mesh filename="package://upperleg_9.stl"/>
</geometry>
<material name="upperleg_9_material">
<color rgba="0.917647 0.917647 0.917647 1.0"/>
</material>
</visual>
<collision>
<origin xyz="0.165 -0.00108365 -0.032916" rpy="1.5708 1.5708 0" />
<geometry>
<mesh filename="package://upperleg_9.stl"/>
</geometry>
<material name="upperleg_9_material">
<color rgba="0.917647 0.917647 0.917647 1.0"/>
</material>
</collision>
<inertial>
<origin xyz="-0.000592499 0.0567057 -0.043972" rpy="0 0 0"/>
<mass value="0.97" />
<inertia ixx="0.00309778" ixy="3.64215e-05"  ixz="2.28223e-05" iyy="0.00465531" iyz="-0.000182553" izz="0.00543222" />
</inertial>
</link>

<link name="lowerleg_2">
<visual>
<origin xyz="0.165 0.201084 -0.0325" rpy="-1.5708 -1.5708 0" />
<geometry>
<mesh filename="package://lowerleg_2.stl"/>
</geometry>
<material name="lowerleg_2_material">
<color rgba="0.615686 0.811765 0.929412 1.0"/>
</material>
</visual>
<collision>
<origin xyz="0.165 0.201084 -0.0325" rpy="-1.5708 -1.5708 0" />
<geometry>
<mesh filename="package://lowerleg_2.stl"/>
</geometry>
<material name="lowerleg_2_material">
<color rgba="0.615686 0.811765 0.929412 1.0"/>
</material>
</collision>
<visual>
<origin xyz="0.165 0.201084 -0.0325" rpy="-1.5708 -1.5708 0" />
<geometry>
<mesh filename="package://lowerleg_1.stl"/>
</geometry>
<material name="lowerleg_1_material">
<color rgba="0.615686 0.811765 0.929412 1.0"/>
</material>
</visual>
<collision>
<origin xyz="0.165 0.201084 -0.0325" rpy="-1.5708 -1.5708 0" />
<geometry>
<mesh filename="package://lowerleg_1.stl"/>
</geometry>
<material name="lowerleg_1_material">
<color rgba="0.615686 0.811765 0.929412 1.0"/>
</material>
</collision>
<visual>
<origin xyz="0.165 0.201084 -0.0325" rpy="-1.5708 -1.5708 0" />
<geometry>
<mesh filename="package://foot.stl"/>
</geometry>
<material name="foot_material">
<color rgba="0.815686 0.00392157 0.00392157 1.0"/>
</material>
</visual>
<collision>
<origin xyz="0.165 0.201084 -0.0325" rpy="-1.5708 -1.5708 0" />
<geometry>
<mesh filename="package://foot.stl"/>
</geometry>
<material name="foot_material">
<color rgba="0.815686 0.00392157 0.00392157 1.0"/>
</material>
</collision>
<visual>
<origin xyz="0.165 0.201114 -0.03229" rpy="-1.5708 -1.5708 0" />
<geometry>
<mesh filename="package://lowerleg_3.stl"/>
</geometry>
<material name="lowerleg_3_material">
<color rgba="0.615686 0.811765 0.929412 1.0"/>
</material>
</visual>
<collision>
<origin xyz="0.165 0.201114 -0.03229" rpy="-1.5708 -1.5708 0" />
<geometry>
<mesh filename="package://lowerleg_3.stl"/>
</geometry>
<material name="lowerleg_3_material">
<color rgba="0.615686 0.811765 0.929412 1.0"/>
</material>
</collision>
<inertial>
<origin xyz="2.76478e-06 -0.0634662 -0.0415243" rpy="0 0 0"/>
<mass value="0.34" />
<inertia ixx="0.0024225" ixy="-3.78677e-06"  ixz="5.33358e-08" iyy="0.00107662" iyz="-0.000776024" izz="0.00248712" />
</inertial>
</link>

<link name="foot_lr">
<inertial>
<origin xyz="0 0 0" rpy="0 0 0" />
<mass value="1e-9" />
<inertia ixx="0" ixy="0" ixz="0" iyy="0" iyz="0" izz="0" />
</inertial>
</link>
<joint name="foot_lr_frame" type="fixed">
<origin xyz="1.44661e-05 -0.195916 -0.0978296" rpy="-1.5708 1.5708 0" />
<parent link="lowerleg_2" />
<child link="foot_lr" />
<axis xyz="0 0 0"/>
</joint>

<joint name="ankle_fr" type="revolute">
<origin xyz="-4.21885e-15 0.2 -0.065516" rpy="-3.14159 8.47616e-16 3.33067e-16" />
<parent link="upperleg_2" />
<child link="lowerleg_2" />
<axis xyz="0 0 1"/>
<limit effort="1" velocity="20" lower="-2.35619" upper="2.35619"/>
<joint_properties friction="0.0"/>
</joint>

<joint name="knee_fr" type="revolute">
<origin xyz="0.0319278 -1.83141e-07 -0.1995" rpy="-3.14159 1.5708 0" />
<parent link="mirrorhip" />
<child link="upperleg_2" />
<axis xyz="0 0 1"/>
<limit effort="1" velocity="20" lower="-0.349066" upper="0.872665"/>
<joint_properties friction="0.0"/>
</joint>

<joint name="hip_fr" type="revolute">
<origin xyz="-0.126016 -0.0654131 0.0733429" rpy="1.5708 2.03529e-14 -3.14159" />
<parent link="body" />
<child link="mirrorhip" />
<axis xyz="0 0 1"/>
<limit effort="1" velocity="20" lower="-0.523599" upper="1.39626"/>
<joint_properties friction="0.0"/>
</joint>

<link name="mirrorhip_2">
<visual>
<origin xyz="0.0606938 0.0011249 0.242549" rpy="1.5708 5.07447e-15 3.88578e-16" />
<geometry>
<mesh filename="package://hipm_3.stl"/>
</geometry>
<material name="hipm_3_material">
<color rgba="0.498039 0.498039 0.498039 1.0"/>
</material>
</visual>
<collision>
<origin xyz="0.0606938 0.0011249 0.242549" rpy="1.5708 5.07447e-15 3.88578e-16" />
<geometry>
<mesh filename="package://hipm_3.stl"/>
</geometry>
<material name="hipm_3_material">
<color rgba="0.498039 0.498039 0.498039 1.0"/>
</material>
</collision>
<visual>
<origin xyz="0.0647278 0.00108347 0.242" rpy="1.5708 -2.53871e-14 6.61138e-14" />
<geometry>
<mesh filename="package://hipm_19.stl"/>
</geometry>
<material name="hipm_19_material">
<color rgba="0.498039 0.498039 0.498039 1.0"/>
</material>
</visual>
<collision>
<origin xyz="0.0647278 0.00108347 0.242" rpy="1.5708 -2.53871e-14 6.61138e-14" />
<geometry>
<mesh filename="package://hipm_19.stl"/>
</geometry>
<material name="hipm_19_material">
<color rgba="0.498039 0.498039 0.498039 1.0"/>
</material>
</collision>
<visual>
<origin xyz="0.0606278 0.00108347 0.242" rpy="1.5708 -6.89928e-15 -8.32667e-16" />
<geometry>
<mesh filename="package://hipm_6.stl"/>
</geometry>
<material name="hipm_6_material">
<color rgba="0.498039 0.498039 0.498039 1.0"/>
</material>
</visual>
<collision>
<origin xyz="0.0606278 0.00108347 0.242" rpy="1.5708 -6.89928e-15 -8.32667e-16" />
<geometry>
<mesh filename="package://hipm_6.stl"/>
</geometry>
<material name="hipm_6_material">
<color rgba="0.498039 0.498039 0.498039 1.0"/>
</material>
</collision>
<visual>
<origin xyz="0.0606938 0.00108347 0.242" rpy="1.5708 -1.26295e-14 1.99888e-24" />
<geometry>
<mesh filename="package://hipm_8.stl"/>
</geometry>
<material name="hipm_8_material">
<color rgba="0.498039 0.498039 0.498039 1.0"/>
</material>
</visual>
<collision>
<origin xyz="0.0606938 0.00108347 0.242" rpy="1.5708 -1.26295e-14 1.99888e-24" />
<geometry>
<mesh filename="package://hipm_8.stl"/>
</geometry>
<material name="hipm_8_material">
<color rgba="0.498039 0.498039 0.498039 1.0"/>
</material>
</collision>
<visual>
<origin xyz="0.0606938 0.0011249 0.242549" rpy="1.5708 5.05589e-15 1.94289e-15" />
<geometry>
<mesh filename="package://hipm_2.stl"/>
</geometry>
<material name="hipm_2_material">
<color rgba="0.498039 0.498039 0.498039 1.0"/>
</material>
</visual>
<collision>
<origin xyz="0.0606938 0.0011249 0.242549" rpy="1.5708 5.05589e-15 1.94289e-15" />
<geometry>
<mesh filename="package://hipm_2.stl"/>
</geometry>
<material name="hipm_2_material">
<color rgba="0.498039 0.498039 0.498039 1.0"/>
</material>
</collision>
<visual>
<origin xyz="0.0607278 0.00108347 0.092" rpy="1.5708 -8.06949e-14 -1.83187e-15" />
<geometry>
<mesh filename="package://motor9225v5_3.stl"/>
</geometry>
<material name="motor9225v5_3_material">
<color rgba="0.498039 0.498039 0.498039 1.0"/>
</material>
</visual>
<collision>
<origin xyz="0.0607278 0.00108347 0.092" rpy="1.5708 -8.06949e-14 -1.83187e-15" />
<geometry>
<mesh filename="package://motor9225v5_3.stl"/>
</geometry>
<material name="motor9225v5_3_material">
<color rgba="0.498039 0.498039 0.498039 1.0"/>
</material>
</collision>
<visual>
<origin xyz="0.0606118 0.117439 0.192906" rpy="0.785398 -1.0648e-14 1.22919e-14" />
<geometry>
<mesh filename="package://hipm_12.stl"/>
</geometry>
<material name="hipm_12_material">
<color rgba="0.498039 0.498039 0.498039 1.0"/>
</material>
</visual>
<collision>
<origin xyz="0.0606118 0.117439 0.192906" rpy="0.785398 -1.0648e-14 1.22919e-14" />
<geometry>
<mesh filename="package://hipm_12.stl"/>
</geometry>
<material name="hipm_12_material">
<color rgba="0.498039 0.498039 0.498039 1.0"/>
</material>
</collision>
<visual>
<origin xyz="0.0606938 0.00108347 0.242" rpy="1.5708 -8.06949e-14 1.11022e-15" />
<geometry>
<mesh filename="package://hipm_14.stl"/>
</geometry>
<material name="hipm_14_material">
<color rgba="0.498039 0.498039 0.498039 1.0"/>
</material>
</visual>
<collision>
<origin xyz="0.0606938 0.00108347 0.242" rpy="1.5708 -8.06949e-14 1.11022e-15" />
<geometry>
<mesh filename="package://hipm_14.stl"/>
</geometry>
<material name="hipm_14_material">
<color rgba="0.498039 0.498039 0.498039 1.0"/>
</material>
</collision>
<visual>
<origin xyz="0.0607278 0.00108347 0.242" rpy="1.5708 -8.96847e-15 -1.11022e-15" />
<geometry>
<mesh filename="package://hipm_11.stl"/>
</geometry>
<material name="hipm_11_material">
<color rgba="0.498039 0.498039 0.498039 1.0"/>
</material>
</visual>
<collision>
<origin xyz="0.0607278 0.00108347 0.242" rpy="1.5708 -8.96847e-15 -1.11022e-15" />
<geometry>
<mesh filename="package://hipm_11.stl"/>
</geometry>
<material name="hipm_11_material">
<color rgba="0.498039 0.498039 0.498039 1.0"/>
</material>
</collision>
<visual>
<origin xyz="0.0607278 0.00108347 0.242" rpy="1.5708 -8.06949e-14 -5.27356e-16" />
<geometry>
<mesh filename="package://hipm_18.stl"/>
</geometry>
<material name="hipm_18_material">
<color rgba="0.498039 0.498039 0.498039 1.0"/>
</material>
</visual>
<collision>
<origin xyz="0.0607278 0.00108347 0.242" rpy="1.5708 -8.06949e-14 -5.27356e-16" />
<geometry>
<mesh filename="package://hipm_18.stl"/>
</geometry>
<material name="hipm_18_material">
<color rgba="0.498039 0.498039 0.498039 1.0"/>
</material>
</collision>
<visual>
<origin xyz="0.0636278 0.00108347 -0.088" rpy="-1.5708 7.77585e-15 5.20417e-14" />
<geometry>
<mesh filename="package://hip_20.stl"/>
</geometry>
<material name="hip_20_material">
<color rgba="0.498039 0.498039 0.498039 1.0"/>
</material>
</visual>
<collision>
<origin xyz="0.0636278 0.00108347 -0.088" rpy="-1.5708 7.77585e-15 5.20417e-14" />
<geometry>
<mesh filename="package://hip_20.stl"/>
</geometry>
<material name="hip_20_material">
<color rgba="0.498039 0.498039 0.498039 1.0"/>
</material>
</collision>
<visual>
<origin xyz="0.0606938 0.00108347 0.242" rpy="1.5708 1.99042e-14 5.04889e-26" />
<geometry>
<mesh filename="package://hipm_9.stl"/>
</geometry>
<material name="hipm_9_material">
<color rgba="0.498039 0.498039 0.498039 1.0"/>
</material>
</visual>
<collision>
<origin xyz="0.0606938 0.00108347 0.242" rpy="1.5708 1.99042e-14 5.04889e-26" />
<geometry>
<mesh filename="package://hipm_9.stl"/>
</geometry>
<material name="hipm_9_material">
<color rgba="0.498039 0.498039 0.498039 1.0"/>
</material>
</collision>
<visual>
<origin xyz="0.0606938 0.00108347 0.242" rpy="1.5708 -8.84601e-15 6.10623e-16" />
<geometry>
<mesh filename="package://hipm_17.stl"/>
</geometry>
<material name="hipm_17_material">
<color rgba="0.498039 0.498039 0.498039 1.0"/>
</material>
</visual>
<collision>
<origin xyz="0.0606938 0.00108347 0.242" rpy="1.5708 -8.84601e-15 6.10623e-16" />
<geometry>
<mesh filename="package://hipm_17.stl"/>
</geometry>
<material name="hipm_17_material">
<color rgba="0.498039 0.498039 0.498039 1.0"/>
</material>
</collision>
<visual>
<origin xyz="0.0300118 -1.83141e-07 0.2015" rpy="1.5708 8.92985e-15 1.5708" />
<geometry>
<mesh filename="package://ams_6.stl"/>
</geometry>
<material name="ams_6_material">
<color rgba="0.498039 0.498039 0.498039 1.0"/>
</material>
</visual>
<collision>
<origin xyz="0.0300118 -1.83141e-07 0.2015" rpy="1.5708 8.92985e-15 1.5708" />
<geometry>
<mesh filename="package://ams_6.stl"/>
</geometry>
<material name="ams_6_material">
<color rgba="0.498039 0.498039 0.498039 1.0"/>
</material>
</collision>
<visual>
<origin xyz="0.0606938 0.00108347 0.242" rpy="1.5708 -8.82673e-15 -4.10784e-24" />
<geometry>
<mesh filename="package://hipm_10.stl"/>
</geometry>
<material name="hipm_10_material">
<color rgba="0.498039 0.498039 0.498039 1.0"/>
</material>
</visual>
<collision>
<origin xyz="0.0606938 0.00108347 0.242" rpy="1.5708 -8.82673e-15 -4.10784e-24" />
<geometry>
<mesh filename="package://hipm_10.stl"/>
</geometry>
<material name="hipm_10_material">
<color rgba="0.498039 0.498039 0.498039 1.0"/>
</material>
</collision>
<visual>
<origin xyz="0.0606938 0.0011249 0.242549" rpy="1.5708 5.07447e-15 3.05311e-16" />
<geometry>
<mesh filename="package://hipm_1.stl"/>
</geometry>
<material name="hipm_1_material">
<color rgba="0.498039 0.498039 0.498039 1.0"/>
</material>
</visual>
<collision>
<origin xyz="0.0606938 0.0011249 0.242549" rpy="1.5708 5.07447e-15 3.05311e-16" />
<geometry>
<mesh filename="package://hipm_1.stl"/>
</geometry>
<material name="hipm_1_material">
<color rgba="0.498039 0.498039 0.498039 1.0"/>
</material>
</collision>
<visual>
<origin xyz="0.0606938 0.00108347 0.2425" rpy="1.5708 5.13344e-15 1.60982e-15" />
<geometry>
<mesh filename="package://hipm_5.stl"/>
</geometry>
<material name="hipm_5_material">
<color rgba="0.498039 0.498039 0.498039 1.0"/>
</material>
</visual>
<collision>
<origin xyz="0.0606938 0.00108347 0.2425" rpy="1.5708 5.13344e-15 1.60982e-15" />
<geometry>
<mesh filename="package://hipm_5.stl"/>
</geometry>
<material name="hipm_5_material">
<color rgba="0.498039 0.498039 0.498039 1.0"/>
</material>
</collision>
<visual>
<origin xyz="0.0606278 0.00108347 0.242" rpy="1.5708 -6.91223e-15 -4.90236e-24" />
<geometry>
<mesh filename="package://hipm_4.stl"/>
</geometry>
<material name="hipm_4_material">
<color rgba="0.498039 0.498039 0.498039 1.0"/>
</material>
</visual>
<collision>
<origin xyz="0.0606278 0.00108347 0.242" rpy="1.5708 -6.91223e-15 -4.90236e-24" />
<geometry>
<mesh filename="package://hipm_4.stl"/>
</geometry>
<material name="hipm_4_material">
<color rgba="0.498039 0.498039 0.498039 1.0"/>
</material>
</collision>
<visual>
<origin xyz="0.0606278 0.00108347 0.242" rpy="1.5708 -8.82673e-15 -4.71845e-16" />
<geometry>
<mesh filename="package://hipm_13.stl"/>
</geometry>
<material name="hipm_13_material">
<color rgba="0.498039 0.498039 0.498039 1.0"/>
</material>
</visual>
<collision>
<origin xyz="0.0606278 0.00108347 0.242" rpy="1.5708 -8.82673e-15 -4.71845e-16" />
<geometry>
<mesh filename="package://hipm_13.stl"/>
</geometry>
<material name="hipm_13_material">
<color rgba="0.498039 0.498039 0.498039 1.0"/>
</material>
</collision>
<visual>
<origin xyz="0.0606938 0.00108347 0.242" rpy="1.5708 9.68227e-15 0" />
<geometry>
<mesh filename="package://hipm_7.stl"/>
</geometry>
<material name="hipm_7_material">
<color rgba="0.498039 0.498039 0.498039 1.0"/>
</material>
</visual>
<collision>
<origin xyz="0.0606938 0.00108347 0.242" rpy="1.5708 9.68227e-15 0" />
<geometry>
<mesh filename="package://hipm_7.stl"/>
</geometry>
<material name="hipm_7_material">
<color rgba="0.498039 0.498039 0.498039 1.0"/>
</material>
</collision>
<visual>
<origin xyz="0.0299278 -1.83141e-07 0.2015" rpy="1.5708 8.92194e-15 1.5708" />
<geometry>
<mesh filename="package://ams_5.stl"/>
</geometry>
<material name="ams_5_material">
<color rgba="0.498039 0.498039 0.498039 1.0"/>
</material>
</visual>
<collision>
<origin xyz="0.0299278 -1.83141e-07 0.2015" rpy="1.5708 8.92194e-15 1.5708" />
<geometry>
<mesh filename="package://ams_5.stl"/>
</geometry>
<material name="ams_5_material">
<color rgba="0.498039 0.498039 0.498039 1.0"/>
</material>
</collision>
<visual>
<origin xyz="0.0607278 0.00108347 0.242" rpy="1.5708 -7.99003e-14 -5.27356e-16" />
<geometry>
<mesh filename="package://hipm_15.stl"/>
</geometry>
<material name="hipm_15_material">
<color rgba="0.498039 0.498039 0.498039 1.0"/>
</material>
</visual>
<collision>
<origin xyz="0.0607278 0.00108347 0.242" rpy="1.5708 -7.99003e-14 -5.27356e-16" />
<geometry>
<mesh filename="package://hipm_15.stl"/>
</geometry>
<material name="hipm_15_material">
<color rgba="0.498039 0.498039 0.498039 1.0"/>
</material>
</collision>
<visual>
<origin xyz="0.0606938 0.117439 0.192906" rpy="0.785398 -9.93164e-15 -1.40189e-14" />
<geometry>
<mesh filename="package://hipm_16.stl"/>
</geometry>
<material name="hipm_16_material">
<color rgba="0.498039 0.498039 0.498039 1.0"/>
</material>
</visual>
<collision>
<origin xyz="0.0606938 0.117439 0.192906" rpy="0.785398 -9.93164e-15 -1.40189e-14" />
<geometry>
<mesh filename="package://hipm_16.stl"/>
</geometry>
<material name="hipm_16_material">
<color rgba="0.498039 0.498039 0.498039 1.0"/>
</material>
</collision>
<inertial>
<origin xyz="-0.0166451 -7.90316e-05 0.141378" rpy="0 0 0"/>
<mass value="1.23081" />
<inertia ixx="0.00905897" ixy="1.5955e-06"  ixz="-0.000220206" iyy="0.00924287" iyz="7.16432e-06" izz="0.00199167" />
</inertial>
</link>

<link name="upperleg_3">
<visual>
<origin xyz="0.165 -0.00108365 -0.032916" rpy="1.5708 1.5708 0" />
<geometry>
<mesh filename="package://upperleg_7.stl"/>
</geometry>
<material name="upperleg_7_material">
<color rgba="0.917647 0.917647 0.917647 1.0"/>
</material>
</visual>
<collision>
<origin xyz="0.165 -0.00108365 -0.032916" rpy="1.5708 1.5708 0" />
<geometry>
<mesh filename="package://upperleg_7.stl"/>
</geometry>
<material name="upperleg_7_material">
<color rgba="0.917647 0.917647 0.917647 1.0"/>
</material>
</collision>
<visual>
<origin xyz="0.165 -0.00108365 -0.032916" rpy="1.5708 1.5708 0" />
<geometry>
<mesh filename="package://upperleg_10.stl"/>
</geometry>
<material name="upperleg_10_material">
<color rgba="0.917647 0.917647 0.917647 1.0"/>
</material>
</visual>
<collision>
<origin xyz="0.165 -0.00108365 -0.032916" rpy="1.5708 1.5708 0" />
<geometry>
<mesh filename="package://upperleg_10.stl"/>
</geometry>
<material name="upperleg_10_material">
<color rgba="0.917647 0.917647 0.917647 1.0"/>
</material>
</collision>
<visual>
<origin xyz="0.165 -0.00108365 -0.032916" rpy="1.5708 1.5708 0" />
<geometry>
<mesh filename="package://upperleg_9.stl"/>
</geometry>
<material name="upperleg_9_material">
<color rgba="0.917647 0.917647 0.917647 1.0"/>
</material>
</visual>
<collision>
<origin xyz="0.165 -0.00108365 -0.032916" rpy="1.5708 1.5708 0" />
<geometry>
<mesh filename="package://upperleg_9.stl"/>
</geometry>
<material name="upperleg_9_material">
<color rgba="0.917647 0.917647 0.917647 1.0"/>
</material>
</collision>
<visual>
<origin xyz="0.115906 -0.117439 -0.032916" rpy="2.35619 1.5708 0" />
<geometry>
<mesh filename="package://upperleg_13.stl"/>
</geometry>
<material name="upperleg_13_material">
<color rgba="0.917647 0.917647 0.917647 1.0"/>
</material>
</visual>
<collision>
<origin xyz="0.115906 -0.117439 -0.032916" rpy="2.35619 1.5708 0" />
<geometry>
<mesh filename="package://upperleg_13.stl"/>
</geometry>
<material name="upperleg_13_material">
<color rgba="0.917647 0.917647 0.917647 1.0"/>
</material>
</collision>
<visual>
<origin xyz="0.165 -0.00108365 -0.033016" rpy="1.5708 1.5708 0" />
<geometry>
<mesh filename="package://upperleg_15.stl"/>
</geometry>
<material name="upperleg_15_material">
<color rgba="0.917647 0.917647 0.917647 1.0"/>
</material>
</visual>
<collision>
<origin xyz="0.165 -0.00108365 -0.033016" rpy="1.5708 1.5708 0" />
<geometry>
<mesh filename="package://upperleg_15.stl"/>
</geometry>
<material name="upperleg_15_material">
<color rgba="0.917647 0.917647 0.917647 1.0"/>
</material>
</collision>
<visual>
<origin xyz="0.165 -0.00108365 -0.032816" rpy="1.5708 1.5708 0" />
<geometry>
<mesh filename="package://upperleg_14.stl"/>
</geometry>
<material name="upperleg_14_material">
<color rgba="0.917647 0.917647 0.917647 1.0"/>
</material>
</visual>
<collision>
<origin xyz="0.165 -0.00108365 -0.032816" rpy="1.5708 1.5708 0" />
<geometry>
<mesh filename="package://upperleg_14.stl"/>
</geometry>
<material name="upperleg_14_material">
<color rgba="0.917647 0.917647 0.917647 1.0"/>
</material>
</collision>
<visual>
<origin xyz="0.165 -0.00108365 -0.032916" rpy="1.5708 1.5708 0" />
<geometry>
<mesh filename="package://upperleg_8.stl"/>
</geometry>
<material name="upperleg_8_material">
<color rgba="0.917647 0.917647 0.917647 1.0"/>
</material>
</visual>
<collision>
<origin xyz="0.165 -0.00108365 -0.032916" rpy="1.5708 1.5708 0" />
<geometry>
<mesh filename="package://upperleg_8.stl"/>
</geometry>
<material name="upperleg_8_material">
<color rgba="0.917647 0.917647 0.917647 1.0"/>
</material>
</collision>
<visual>
<origin xyz="0.165 -0.00108365 -0.032916" rpy="1.5708 1.5708 0" />
<geometry>
<mesh filename="package://upperleg_11.stl"/>
</geometry>
<material name="upperleg_11_material">
<color rgba="0.917647 0.917647 0.917647 1.0"/>
</material>
</visual>
<collision>
<origin xyz="0.165 -0.00108365 -0.032916" rpy="1.5708 1.5708 0" />
<geometry>
<mesh filename="package://upperleg_11.stl"/>
</geometry>
<material name="upperleg_11_material">
<color rgba="0.917647 0.917647 0.917647 1.0"/>
</material>
</collision>
<visual>
<origin xyz="0.165 -0.00108365 -0.032916" rpy="1.5708 1.5708 0" />
<geometry>
<mesh filename="package://upperleg_4.stl"/>
</geometry>
<material name="upperleg_4_material">
<color rgba="0.917647 0.917647 0.917647 1.0"/>
</material>
</visual>
<collision>
<origin xyz="0.165 -0.00108365 -0.032916" rpy="1.5708 1.5708 0" />
<geometry>
<mesh filename="package://upperleg_4.stl"/>
</geometry>
<material name="upperleg_4_material">
<color rgba="0.917647 0.917647 0.917647 1.0"/>
</material>
</collision>
<visual>
<origin xyz="0.165 -0.00108365 -0.032916" rpy="1.5708 1.5708 0" />
<geometry>
<mesh filename="package://upperleg_3.stl"/>
</geometry>
<material name="upperleg_3_material">
<color rgba="0.917647 0.917647 0.917647 1.0"/>
</material>
</visual>
<collision>
<origin xyz="0.165 -0.00108365 -0.032916" rpy="1.5708 1.5708 0" />
<geometry>
<mesh filename="package://upperleg_3.stl"/>
</geometry>
<material name="upperleg_3_material">
<color rgba="0.917647 0.917647 0.917647 1.0"/>
</material>
</collision>
<visual>
<origin xyz="0.00843847 0.0124486 -0.028916" rpy="0.523599 1.5708 0" />
<geometry>
<mesh filename="package://motor9225v5_1.stl"/>
</geometry>
<material name="motor9225v5_1_material">
<color rgba="0.917647 0.917647 0.917647 1.0"/>
</material>
</visual>
<collision>
<origin xyz="0.00843847 0.0124486 -0.028916" rpy="0.523599 1.5708 0" />
<geometry>
<mesh filename="package://motor9225v5_1.stl"/>
</geometry>
<material name="motor9225v5_1_material">
<color rgba="0.917647 0.917647 0.917647 1.0"/>
</material>
</collision>
<visual>
<origin xyz="0.164806 -0.00131537 -0.0323548" rpy="1.5708 1.5708 0" />
<geometry>
<mesh filename="package://upperleg_2.stl"/>
</geometry>
<material name="upperleg_2_material">
<color rgba="0.917647 0.917647 0.917647 1.0"/>
</material>
</visual>
<collision>
<origin xyz="0.164806 -0.00131537 -0.0323548" rpy="1.5708 1.5708 0" />
<geometry>
<mesh filename="package://upperleg_2.stl"/>
</geometry>
<material name="upperleg_2_material">
<color rgba="0.917647 0.917647 0.917647 1.0"/>
</material>
</collision>
<visual>
<origin xyz="-0.0766619 -0.0781945 0.042084" rpy="0.785398 1.5708 0" />
<geometry>
<mesh filename="package://ams_1.stl"/>
</geometry>
<material name="ams_1_material">
<color rgba="0.917647 0.917647 0.917647 1.0"/>
</material>
</visual>
<collision>
<origin xyz="-0.0766619 -0.0781945 0.042084" rpy="0.785398 1.5708 0" />
<geometry>
<mesh filename="package://ams_1.stl"/>
</geometry>
<material name="ams_1_material">
<color rgba="0.917647 0.917647 0.917647 1.0"/>
</material>
</collision>
<visual>
<origin xyz="0.165 -0.00108365 -0.032916" rpy="1.5708 1.5708 0" />
<geometry>
<mesh filename="package://upperleg_5.stl"/>
</geometry>
<material name="upperleg_5_material">
<color rgba="0.917647 0.917647 0.917647 1.0"/>
</material>
</visual>
<collision>
<origin xyz="0.165 -0.00108365 -0.032916" rpy="1.5708 1.5708 0" />
<geometry>
<mesh filename="package://upperleg_5.stl"/>
</geometry>
<material name="upperleg_5_material">
<color rgba="0.917647 0.917647 0.917647 1.0"/>
</material>
</collision>
<visual>
<origin xyz="0.165 -0.00108365 -0.032916" rpy="1.5708 1.5708 0" />
<geometry>
<mesh filename="package://upperleg_6.stl"/>
</geometry>
<material name="upperleg_6_material">
<color rgba="0.917647 0.917647 0.917647 1.0"/>
</material>
</visual>
<collision>
<origin xyz="0.165 -0.00108365 -0.032916" rpy="1.5708 1.5708 0" />
<geometry>
<mesh filename="package://upperleg_6.stl"/>
</geometry>
<material name="upperleg_6_material">
<color rgba="0.917647 0.917647 0.917647 1.0"/>
</material>
</collision>
<visual>
<origin xyz="0.165 -0.00108365 -0.032916" rpy="1.5708 1.5708 0" />
<geometry>
<mesh filename="package://upperleg_12.stl"/>
</geometry>
<material name="upperleg_12_material">
<color rgba="0.917647 0.917647 0.917647 1.0"/>
</material>
</visual>
<collision>
<origin xyz="0.165 -0.00108365 -0.032916" rpy="1.5708 1.5708 0" />
<geometry>
<mesh filename="package://upperleg_12.stl"/>
</geometry>
<material name="upperleg_12_material">
<color rgba="0.917647 0.917647 0.917647 1.0"/>
</material>
</collision>
<visual>
<origin xyz="-0.106049 0.027294 0.042084" rpy="1.8326 1.5708 0" />
<geometry>
<mesh filename="package://ams_2.stl"/>
</geometry>
<material name="ams_2_material">
<color rgba="0.917647 0.917647 0.917647 1.0"/>
</material>
</visual>
<collision>
<origin xyz="-0.106049 0.027294 0.042084" rpy="1.8326 1.5708 0" />
<geometry>
<mesh filename="package://ams_2.stl"/>
</geometry>
<material name="ams_2_material">
<color rgba="0.917647 0.917647 0.917647 1.0"/>
</material>
</collision>
<visual>
<origin xyz="0.165 -0.00108365 -0.032916" rpy="1.5708 1.5708 0" />
<geometry>
<mesh filename="package://upperleg_1.stl"/>
</geometry>
<material name="upperleg_1_material">
<color rgba="0.917647 0.917647 0.917647 1.0"/>
</material>
</visual>
<collision>
<origin xyz="0.165 -0.00108365 -0.032916" rpy="1.5708 1.5708 0" />
<geometry>
<mesh filename="package://upperleg_1.stl"/>
</geometry>
<material name="upperleg_1_material">
<color rgba="0.917647 0.917647 0.917647 1.0"/>
</material>
</collision>
<inertial>
<origin xyz="-0.000592499 0.0567057 -0.043972" rpy="0 0 0"/>
<mass value="0.97" />
<inertia ixx="0.00309778" ixy="3.64215e-05"  ixz="2.28223e-05" iyy="0.00465531" iyz="-0.000182553" izz="0.00543222" />
</inertial>
</link>

<link name="lowerleg_3">
<visual>
<origin xyz="0.165 0.201084 -0.0325" rpy="-1.5708 -1.5708 0" />
<geometry>
<mesh filename="package://lowerleg_2.stl"/>
</geometry>
<material name="lowerleg_2_material">
<color rgba="0.615686 0.811765 0.929412 1.0"/>
</material>
</visual>
<collision>
<origin xyz="0.165 0.201084 -0.0325" rpy="-1.5708 -1.5708 0" />
<geometry>
<mesh filename="package://lowerleg_2.stl"/>
</geometry>
<material name="lowerleg_2_material">
<color rgba="0.615686 0.811765 0.929412 1.0"/>
</material>
</collision>
<visual>
<origin xyz="0.165 0.201084 -0.0325" rpy="-1.5708 -1.5708 0" />
<geometry>
<mesh filename="package://lowerleg_1.stl"/>
</geometry>
<material name="lowerleg_1_material">
<color rgba="0.615686 0.811765 0.929412 1.0"/>
</material>
</visual>
<collision>
<origin xyz="0.165 0.201084 -0.0325" rpy="-1.5708 -1.5708 0" />
<geometry>
<mesh filename="package://lowerleg_1.stl"/>
</geometry>
<material name="lowerleg_1_material">
<color rgba="0.615686 0.811765 0.929412 1.0"/>
</material>
</collision>
<visual>
<origin xyz="0.165 0.201114 -0.03229" rpy="-1.5708 -1.5708 0" />
<geometry>
<mesh filename="package://lowerleg_3.stl"/>
</geometry>
<material name="lowerleg_3_material">
<color rgba="0.615686 0.811765 0.929412 1.0"/>
</material>
</visual>
<collision>
<origin xyz="0.165 0.201114 -0.03229" rpy="-1.5708 -1.5708 0" />
<geometry>
<mesh filename="package://lowerleg_3.stl"/>
</geometry>
<material name="lowerleg_3_material">
<color rgba="0.615686 0.811765 0.929412 1.0"/>
</material>
</collision>
<visual>
<origin xyz="0.165 0.201084 -0.0325" rpy="-1.5708 -1.5708 0" />
<geometry>
<mesh filename="package://foot.stl"/>
</geometry>
<material name="foot_material">
<color rgba="0.815686 0.00392157 0.00392157 1.0"/>
</material>
</visual>
<collision>
<origin xyz="0.165 0.201084 -0.0325" rpy="-1.5708 -1.5708 0" />
<geometry>
<mesh filename="package://foot.stl"/>
</geometry>
<material name="foot_material">
<color rgba="0.815686 0.00392157 0.00392157 1.0"/>
</material>
</collision>
<inertial>
<origin xyz="2.76478e-06 -0.0634662 -0.0415243" rpy="0 0 0"/>
<mass value="0.34" />
<inertia ixx="0.0024225" ixy="-3.78677e-06"  ixz="5.33358e-08" iyy="0.00107662" iyz="-0.000776024" izz="0.00248712" />
</inertial>
</link>

<link name="foot_bl">
<inertial>
<origin xyz="0 0 0" rpy="0 0 0" />
<mass value="1e-9" />
<inertia ixx="0" ixy="0" ixz="0" iyy="0" iyz="0" izz="0" />
</inertial>
</link>
<joint name="foot_bl_frame" type="fixed">
<origin xyz="1.44661e-05 -0.195916 -0.0978296" rpy="-1.5708 -1.5708 0" />
<parent link="lowerleg_3" />
<child link="foot_bl" />
<axis xyz="0 0 0"/>
</joint>

<joint name="ankle_bl" type="revolute">
<origin xyz="-4.32987e-15 0.2 -0.065516" rpy="-3.14159 -9.28741e-16 -3.33067e-16" />
<parent link="upperleg_3" />
<child link="lowerleg_3" />
<axis xyz="0 0 1"/>
<limit effort="1" velocity="20" lower="-2.35619" upper="2.35619"/>
<joint_properties friction="0.0"/>
</joint>

<joint name="knee_bl" type="revolute">
<origin xyz="0.0319278 -1.83141e-07 0.077" rpy="-3.14159 1.5708 0" />
<parent link="mirrorhip_2" />
<child link="upperleg_3" />
<axis xyz="0 0 1"/>
<limit effort="1" velocity="20" lower="-0.349066" upper="0.872665"/>
<joint_properties friction="0.0"/>
</joint>

<joint name="hip_bl" type="revolute">
<origin xyz="0.123746 0.341324 0.0733429" rpy="1.5708 -1.19349e-15 6.38026e-10" />
<parent link="body" />
<child link="mirrorhip_2" />
<axis xyz="0 0 1"/>
<limit effort="1" velocity="20" lower="-0.523599" upper="1.39626"/>
<joint_properties friction="0.0"/>
</joint>

<link name="hip_2">
<visual>
<origin xyz="0.0606938 0.00108347 0.0165" rpy="-1.5708 -1.0884e-15 -2.77556e-17" />
<geometry>
<mesh filename="package://hip_6.stl"/>
</geometry>
<material name="hip_6_material">
<color rgba="0.498039 0.498039 0.498039 1.0"/>
</material>
</visual>
<collision>
<origin xyz="0.0606938 0.00108347 0.0165" rpy="-1.5708 -1.0884e-15 -2.77556e-17" />
<geometry>
<mesh filename="package://hip_6.stl"/>
</geometry>
<material name="hip_6_material">
<color rgba="0.498039 0.498039 0.498039 1.0"/>
</material>
</collision>
<visual>
<origin xyz="0.0647278 0.00108347 0.0165" rpy="-1.5708 1.48202e-14 6.76681e-14" />
<geometry>
<mesh filename="package://hip_19.stl"/>
</geometry>
<material name="hip_19_material">
<color rgba="0.498039 0.498039 0.498039 1.0"/>
</material>
</visual>
<collision>
<origin xyz="0.0647278 0.00108347 0.0165" rpy="-1.5708 1.48202e-14 6.76681e-14" />
<geometry>
<mesh filename="package://hip_19.stl"/>
</geometry>
<material name="hip_19_material">
<color rgba="0.498039 0.498039 0.498039 1.0"/>
</material>
</collision>
<visual>
<origin xyz="0.0606938 -0.115907 0.0640611" rpy="-2.35619 -1.50847e-14 4.49133e-16" />
<geometry>
<mesh filename="package://hip_16.stl"/>
</geometry>
<material name="hip_16_material">
<color rgba="0.498039 0.498039 0.498039 1.0"/>
</material>
</visual>
<collision>
<origin xyz="0.0606938 -0.115907 0.0640611" rpy="-2.35619 -1.50847e-14 4.49133e-16" />
<geometry>
<mesh filename="package://hip_16.stl"/>
</geometry>
<material name="hip_16_material">
<color rgba="0.498039 0.498039 0.498039 1.0"/>
</material>
</collision>
<visual>
<origin xyz="0.0606938 0.00108347 0.0165" rpy="-1.5708 1.02219e-14 -5.55111e-17" />
<geometry>
<mesh filename="package://hip_11.stl"/>
</geometry>
<material name="hip_11_material">
<color rgba="0.498039 0.498039 0.498039 1.0"/>
</material>
</visual>
<collision>
<origin xyz="0.0606938 0.00108347 0.0165" rpy="-1.5708 1.02219e-14 -5.55111e-17" />
<geometry>
<mesh filename="package://hip_11.stl"/>
</geometry>
<material name="hip_11_material">
<color rgba="0.498039 0.498039 0.498039 1.0"/>
</material>
</collision>
<visual>
<origin xyz="0.0299278 -1.83141e-07 0.057" rpy="-1.5708 1.38778e-16 1.5708" />
<geometry>
<mesh filename="package://ams_3.stl"/>
</geometry>
<material name="ams_3_material">
<color rgba="0.498039 0.498039 0.498039 1.0"/>
</material>
</visual>
<collision>
<origin xyz="0.0299278 -1.83141e-07 0.057" rpy="-1.5708 1.38778e-16 1.5708" />
<geometry>
<mesh filename="package://ams_3.stl"/>
</geometry>
<material name="ams_3_material">
<color rgba="0.498039 0.498039 0.498039 1.0"/>
</material>
</collision>
<visual>
<origin xyz="0.0636278 0.00108347 0.0165" rpy="-1.5708 1.48514e-14 5.35017e-14" />
<geometry>
<mesh filename="package://hip_20.stl"/>
</geometry>
<material name="hip_20_material">
<color rgba="0.498039 0.498039 0.498039 1.0"/>
</material>
</visual>
<collision>
<origin xyz="0.0636278 0.00108347 0.0165" rpy="-1.5708 1.48514e-14 5.35017e-14" />
<geometry>
<mesh filename="package://hip_20.stl"/>
</geometry>
<material name="hip_20_material">
<color rgba="0.498039 0.498039 0.498039 1.0"/>
</material>
</collision>
<visual>
<origin xyz="0.0606938 0.00108347 0.0165" rpy="-1.5708 7.07798e-14 8.74301e-16" />
<geometry>
<mesh filename="package://hip_14.stl"/>
</geometry>
<material name="hip_14_material">
<color rgba="0.498039 0.498039 0.498039 1.0"/>
</material>
</visual>
<collision>
<origin xyz="0.0606938 0.00108347 0.0165" rpy="-1.5708 7.07798e-14 8.74301e-16" />
<geometry>
<mesh filename="package://hip_14.stl"/>
</geometry>
<material name="hip_14_material">
<color rgba="0.498039 0.498039 0.498039 1.0"/>
</material>
</collision>
<visual>
<origin xyz="0.0607278 0.00108347 0.0165" rpy="-1.5708 7.26821e-14 1.45717e-15" />
<geometry>
<mesh filename="package://hip_15.stl"/>
</geometry>
<material name="hip_15_material">
<color rgba="0.498039 0.498039 0.498039 1.0"/>
</material>
</visual>
<collision>
<origin xyz="0.0607278 0.00108347 0.0165" rpy="-1.5708 7.26821e-14 1.45717e-15" />
<geometry>
<mesh filename="package://hip_15.stl"/>
</geometry>
<material name="hip_15_material">
<color rgba="0.498039 0.498039 0.498039 1.0"/>
</material>
</collision>
<visual>
<origin xyz="0.0627278 0.00108347 0.0165" rpy="-1.5708 -1.59843e-15 1.13798e-15" />
<geometry>
<mesh filename="package://hip_8.stl"/>
</geometry>
<material name="hip_8_material">
<color rgba="0.498039 0.498039 0.498039 1.0"/>
</material>
</visual>
<collision>
<origin xyz="0.0627278 0.00108347 0.0165" rpy="-1.5708 -1.59843e-15 1.13798e-15" />
<geometry>
<mesh filename="package://hip_8.stl"/>
</geometry>
<material name="hip_8_material">
<color rgba="0.498039 0.498039 0.498039 1.0"/>
</material>
</collision>
<visual>
<origin xyz="0.0606118 -0.115907 0.0640611" rpy="-2.35619 1.21328e-14 -8.06187e-16" />
<geometry>
<mesh filename="package://hip_9.stl"/>
</geometry>
<material name="hip_9_material">
<color rgba="0.498039 0.498039 0.498039 1.0"/>
</material>
</visual>
<collision>
<origin xyz="0.0606118 -0.115907 0.0640611" rpy="-2.35619 1.21328e-14 -8.06187e-16" />
<geometry>
<mesh filename="package://hip_9.stl"/>
</geometry>
<material name="hip_9_material">
<color rgba="0.498039 0.498039 0.498039 1.0"/>
</material>
</collision>
<visual>
<origin xyz="0.0606938 0.00108347 0.0165" rpy="-1.5708 -5.06484e-30 0" />
<geometry>
<mesh filename="package://hip_13.stl"/>
</geometry>
<material name="hip_13_material">
<color rgba="0.498039 0.498039 0.498039 1.0"/>
</material>
</visual>
<collision>
<origin xyz="0.0606938 0.00108347 0.0165" rpy="-1.5708 -5.06484e-30 0" />
<geometry>
<mesh filename="package://hip_13.stl"/>
</geometry>
<material name="hip_13_material">
<color rgba="0.498039 0.498039 0.498039 1.0"/>
</material>
</collision>
<visual>
<origin xyz="0.0300118 -1.83141e-07 0.057" rpy="-1.5708 1.38778e-16 1.5708" />
<geometry>
<mesh filename="package://ams_4.stl"/>
</geometry>
<material name="ams_4_material">
<color rgba="0.498039 0.498039 0.498039 1.0"/>
</material>
</visual>
<collision>
<origin xyz="0.0300118 -1.83141e-07 0.057" rpy="-1.5708 1.38778e-16 1.5708" />
<geometry>
<mesh filename="package://ams_4.stl"/>
</geometry>
<material name="ams_4_material">
<color rgba="0.498039 0.498039 0.498039 1.0"/>
</material>
</collision>
<visual>
<origin xyz="0.0606278 0.00108347 0.0165" rpy="-1.5708 -1.74017e-15 6.93889e-16" />
<geometry>
<mesh filename="package://hip_10.stl"/>
</geometry>
<material name="hip_10_material">
<color rgba="0.498039 0.498039 0.498039 1.0"/>
</material>
</visual>
<collision>
<origin xyz="0.0606278 0.00108347 0.0165" rpy="-1.5708 -1.74017e-15 6.93889e-16" />
<geometry>
<mesh filename="package://hip_10.stl"/>
</geometry>
<material name="hip_10_material">
<color rgba="0.498039 0.498039 0.498039 1.0"/>
</material>
</collision>
<visual>
<origin xyz="0.0606278 0.00108347 0.0165" rpy="-1.5708 -1.74017e-15 -5.55111e-17" />
<geometry>
<mesh filename="package://hip_4.stl"/>
</geometry>
<material name="hip_4_material">
<color rgba="0.498039 0.498039 0.498039 1.0"/>
</material>
</visual>
<collision>
<origin xyz="0.0606278 0.00108347 0.0165" rpy="-1.5708 -1.74017e-15 -5.55111e-17" />
<geometry>
<mesh filename="package://hip_4.stl"/>
</geometry>
<material name="hip_4_material">
<color rgba="0.498039 0.498039 0.498039 1.0"/>
</material>
</collision>
<visual>
<origin xyz="0.0606278 0.00108347 0.0165" rpy="-1.5708 -1.38943e-14 -5.27356e-16" />
<geometry>
<mesh filename="package://hip_1.stl"/>
</geometry>
<material name="hip_1_material">
<color rgba="0.498039 0.498039 0.498039 1.0"/>
</material>
</visual>
<collision>
<origin xyz="0.0606278 0.00108347 0.0165" rpy="-1.5708 -1.38943e-14 -5.27356e-16" />
<geometry>
<mesh filename="package://hip_1.stl"/>
</geometry>
<material name="hip_1_material">
<color rgba="0.498039 0.498039 0.498039 1.0"/>
</material>
</collision>
<visual>
<origin xyz="0.0606278 0.00108347 0.0165" rpy="-1.5708 -2.40519e-14 -5.55111e-17" />
<geometry>
<mesh filename="package://hip_12.stl"/>
</geometry>
<material name="hip_12_material">
<color rgba="0.498039 0.498039 0.498039 1.0"/>
</material>
</visual>
<collision>
<origin xyz="0.0606278 0.00108347 0.0165" rpy="-1.5708 -2.40519e-14 -5.55111e-17" />
<geometry>
<mesh filename="package://hip_12.stl"/>
</geometry>
<material name="hip_12_material">
<color rgba="0.498039 0.498039 0.498039 1.0"/>
</material>
</collision>
<visual>
<origin xyz="0.0607278 0.00108347 0.0165" rpy="-1.5708 7.18682e-14 7.63278e-16" />
<geometry>
<mesh filename="package://hip_18.stl"/>
</geometry>
<material name="hip_18_material">
<color rgba="0.498039 0.498039 0.498039 1.0"/>
</material>
</visual>
<collision>
<origin xyz="0.0607278 0.00108347 0.0165" rpy="-1.5708 7.18682e-14 7.63278e-16" />
<geometry>
<mesh filename="package://hip_18.stl"/>
</geometry>
<material name="hip_18_material">
<color rgba="0.498039 0.498039 0.498039 1.0"/>
</material>
</collision>
<visual>
<origin xyz="0.0607278 0.00108347 0.1665" rpy="-1.5708 7.18682e-14 -1.38778e-16" />
<geometry>
<mesh filename="package://motor9225v5_2.stl"/>
</geometry>
<material name="motor9225v5_2_material">
<color rgba="0.498039 0.498039 0.498039 1.0"/>
</material>
</visual>
<collision>
<origin xyz="0.0607278 0.00108347 0.1665" rpy="-1.5708 7.18682e-14 -1.38778e-16" />
<geometry>
<mesh filename="package://motor9225v5_2.stl"/>
</geometry>
<material name="motor9225v5_2_material">
<color rgba="0.498039 0.498039 0.498039 1.0"/>
</material>
</collision>
<visual>
<origin xyz="0.0606278 0.00108347 0.0165" rpy="-1.5708 -1.38943e-14 -4.71845e-16" />
<geometry>
<mesh filename="package://hip_2.stl"/>
</geometry>
<material name="hip_2_material">
<color rgba="0.498039 0.498039 0.498039 1.0"/>
</material>
</visual>
<collision>
<origin xyz="0.0606278 0.00108347 0.0165" rpy="-1.5708 -1.38943e-14 -4.71845e-16" />
<geometry>
<mesh filename="package://hip_2.stl"/>
</geometry>
<material name="hip_2_material">
<color rgba="0.498039 0.498039 0.498039 1.0"/>
</material>
</collision>
<visual>
<origin xyz="0.0606278 0.00108347 0.0165" rpy="-1.5708 -1.74017e-15 -1.11022e-16" />
<geometry>
<mesh filename="package://hip_5.stl"/>
</geometry>
<material name="hip_5_material">
<color rgba="0.498039 0.498039 0.498039 1.0"/>
</material>
</visual>
<collision>
<origin xyz="0.0606278 0.00108347 0.0165" rpy="-1.5708 -1.74017e-15 -1.11022e-16" />
<geometry>
<mesh filename="package://hip_5.stl"/>
</geometry>
<material name="hip_5_material">
<color rgba="0.498039 0.498039 0.498039 1.0"/>
</material>
</collision>
<visual>
<origin xyz="0.0606938 0.00108347 0.0165" rpy="-1.5708 -1.06912e-15 8.04912e-16" />
<geometry>
<mesh filename="package://hip_17.stl"/>
</geometry>
<material name="hip_17_material">
<color rgba="0.498039 0.498039 0.498039 1.0"/>
</material>
</visual>
<collision>
<origin xyz="0.0606938 0.00108347 0.0165" rpy="-1.5708 -1.06912e-15 8.04912e-16" />
<geometry>
<mesh filename="package://hip_17.stl"/>
</geometry>
<material name="hip_17_material">
<color rgba="0.498039 0.498039 0.498039 1.0"/>
</material>
</collision>
<visual>
<origin xyz="0.0606278 0.00108347 0.0165" rpy="-1.5708 -1.37915e-14 -2.77556e-17" />
<geometry>
<mesh filename="package://hip_7.stl"/>
</geometry>
<material name="hip_7_material">
<color rgba="0.498039 0.498039 0.498039 1.0"/>
</material>
</visual>
<collision>
<origin xyz="0.0606278 0.00108347 0.0165" rpy="-1.5708 -1.37915e-14 -2.77556e-17" />
<geometry>
<mesh filename="package://hip_7.stl"/>
</geometry>
<material name="hip_7_material">
<color rgba="0.498039 0.498039 0.498039 1.0"/>
</material>
</collision>
<visual>
<origin xyz="0.0606278 0.00108347 0.0165" rpy="-1.5708 -1.38943e-14 -5.27356e-16" />
<geometry>
<mesh filename="package://hip_3.stl"/>
</geometry>
<material name="hip_3_material">
<color rgba="0.498039 0.498039 0.498039 1.0"/>
</material>
</visual>
<collision>
<origin xyz="0.0606278 0.00108347 0.0165" rpy="-1.5708 -1.38943e-14 -5.27356e-16" />
<geometry>
<mesh filename="package://hip_3.stl"/>
</geometry>
<material name="hip_3_material">
<color rgba="0.498039 0.498039 0.498039 1.0"/>
</material>
</collision>
<inertial>
<origin xyz="-0.0166609 -7.94503e-05 0.14348" rpy="0 0 0"/>
<mass value="1.23" />
<inertia ixx="0.00898763" ixy="1.61607e-06"  ixz="1.67935e-05" iyy="0.00917046" iyz="-9.7706e-06" izz="0.00199049" />
</inertial>
</link>

<link name="upperleg_4">
<visual>
<origin xyz="0.165 -0.00108365 -0.032916" rpy="1.5708 1.5708 0" />
<geometry>
<mesh filename="package://upperleg_1.stl"/>
</geometry>
<material name="upperleg_1_material">
<color rgba="0.917647 0.917647 0.917647 1.0"/>
</material>
</visual>
<collision>
<origin xyz="0.165 -0.00108365 -0.032916" rpy="1.5708 1.5708 0" />
<geometry>
<mesh filename="package://upperleg_1.stl"/>
</geometry>
<material name="upperleg_1_material">
<color rgba="0.917647 0.917647 0.917647 1.0"/>
</material>
</collision>
<visual>
<origin xyz="0.165 -0.00108365 -0.032916" rpy="1.5708 1.5708 0" />
<geometry>
<mesh filename="package://upperleg_7.stl"/>
</geometry>
<material name="upperleg_7_material">
<color rgba="0.917647 0.917647 0.917647 1.0"/>
</material>
</visual>
<collision>
<origin xyz="0.165 -0.00108365 -0.032916" rpy="1.5708 1.5708 0" />
<geometry>
<mesh filename="package://upperleg_7.stl"/>
</geometry>
<material name="upperleg_7_material">
<color rgba="0.917647 0.917647 0.917647 1.0"/>
</material>
</collision>
<visual>
<origin xyz="0.165 -0.00108365 -0.032916" rpy="1.5708 1.5708 0" />
<geometry>
<mesh filename="package://upperleg_12.stl"/>
</geometry>
<material name="upperleg_12_material">
<color rgba="0.917647 0.917647 0.917647 1.0"/>
</material>
</visual>
<collision>
<origin xyz="0.165 -0.00108365 -0.032916" rpy="1.5708 1.5708 0" />
<geometry>
<mesh filename="package://upperleg_12.stl"/>
</geometry>
<material name="upperleg_12_material">
<color rgba="0.917647 0.917647 0.917647 1.0"/>
</material>
</collision>
<visual>
<origin xyz="0.165 -0.00108365 -0.032816" rpy="1.5708 1.5708 0" />
<geometry>
<mesh filename="package://upperleg_14.stl"/>
</geometry>
<material name="upperleg_14_material">
<color rgba="0.917647 0.917647 0.917647 1.0"/>
</material>
</visual>
<collision>
<origin xyz="0.165 -0.00108365 -0.032816" rpy="1.5708 1.5708 0" />
<geometry>
<mesh filename="package://upperleg_14.stl"/>
</geometry>
<material name="upperleg_14_material">
<color rgba="0.917647 0.917647 0.917647 1.0"/>
</material>
</collision>
<visual>
<origin xyz="0.164806 -0.00131537 -0.0323548" rpy="1.5708 1.5708 0" />
<geometry>
<mesh filename="package://upperleg_2.stl"/>
</geometry>
<material name="upperleg_2_material">
<color rgba="0.917647 0.917647 0.917647 1.0"/>
</material>
</visual>
<collision>
<origin xyz="0.164806 -0.00131537 -0.0323548" rpy="1.5708 1.5708 0" />
<geometry>
<mesh filename="package://upperleg_2.stl"/>
</geometry>
<material name="upperleg_2_material">
<color rgba="0.917647 0.917647 0.917647 1.0"/>
</material>
</collision>
<visual>
<origin xyz="0.165 -0.00108365 -0.032916" rpy="1.5708 1.5708 0" />
<geometry>
<mesh filename="package://upperleg_10.stl"/>
</geometry>
<material name="upperleg_10_material">
<color rgba="0.917647 0.917647 0.917647 1.0"/>
</material>
</visual>
<collision>
<origin xyz="0.165 -0.00108365 -0.032916" rpy="1.5708 1.5708 0" />
<geometry>
<mesh filename="package://upperleg_10.stl"/>
</geometry>
<material name="upperleg_10_material">
<color rgba="0.917647 0.917647 0.917647 1.0"/>
</material>
</collision>
<visual>
<origin xyz="0.165 -0.00108365 -0.032916" rpy="1.5708 1.5708 0" />
<geometry>
<mesh filename="package://upperleg_9.stl"/>
</geometry>
<material name="upperleg_9_material">
<color rgba="0.917647 0.917647 0.917647 1.0"/>
</material>
</visual>
<collision>
<origin xyz="0.165 -0.00108365 -0.032916" rpy="1.5708 1.5708 0" />
<geometry>
<mesh filename="package://upperleg_9.stl"/>
</geometry>
<material name="upperleg_9_material">
<color rgba="0.917647 0.917647 0.917647 1.0"/>
</material>
</collision>
<visual>
<origin xyz="0.165 -0.00108365 -0.033016" rpy="1.5708 1.5708 0" />
<geometry>
<mesh filename="package://upperleg_15.stl"/>
</geometry>
<material name="upperleg_15_material">
<color rgba="0.917647 0.917647 0.917647 1.0"/>
</material>
</visual>
<collision>
<origin xyz="0.165 -0.00108365 -0.033016" rpy="1.5708 1.5708 0" />
<geometry>
<mesh filename="package://upperleg_15.stl"/>
</geometry>
<material name="upperleg_15_material">
<color rgba="0.917647 0.917647 0.917647 1.0"/>
</material>
</collision>
<visual>
<origin xyz="0.115906 -0.117439 -0.032916" rpy="2.35619 1.5708 0" />
<geometry>
<mesh filename="package://upperleg_13.stl"/>
</geometry>
<material name="upperleg_13_material">
<color rgba="0.917647 0.917647 0.917647 1.0"/>
</material>
</visual>
<collision>
<origin xyz="0.115906 -0.117439 -0.032916" rpy="2.35619 1.5708 0" />
<geometry>
<mesh filename="package://upperleg_13.stl"/>
</geometry>
<material name="upperleg_13_material">
<color rgba="0.917647 0.917647 0.917647 1.0"/>
</material>
</collision>
<visual>
<origin xyz="-0.106049 0.027294 0.042084" rpy="1.8326 1.5708 0" />
<geometry>
<mesh filename="package://ams_2.stl"/>
</geometry>
<material name="ams_2_material">
<color rgba="0.917647 0.917647 0.917647 1.0"/>
</material>
</visual>
<collision>
<origin xyz="-0.106049 0.027294 0.042084" rpy="1.8326 1.5708 0" />
<geometry>
<mesh filename="package://ams_2.stl"/>
</geometry>
<material name="ams_2_material">
<color rgba="0.917647 0.917647 0.917647 1.0"/>
</material>
</collision>
<visual>
<origin xyz="0.165 -0.00108365 -0.032916" rpy="1.5708 1.5708 0" />
<geometry>
<mesh filename="package://upperleg_4.stl"/>
</geometry>
<material name="upperleg_4_material">
<color rgba="0.917647 0.917647 0.917647 1.0"/>
</material>
</visual>
<collision>
<origin xyz="0.165 -0.00108365 -0.032916" rpy="1.5708 1.5708 0" />
<geometry>
<mesh filename="package://upperleg_4.stl"/>
</geometry>
<material name="upperleg_4_material">
<color rgba="0.917647 0.917647 0.917647 1.0"/>
</material>
</collision>
<visual>
<origin xyz="0.165 -0.00108365 -0.032916" rpy="1.5708 1.5708 0" />
<geometry>
<mesh filename="package://upperleg_3.stl"/>
</geometry>
<material name="upperleg_3_material">
<color rgba="0.917647 0.917647 0.917647 1.0"/>
</material>
</visual>
<collision>
<origin xyz="0.165 -0.00108365 -0.032916" rpy="1.5708 1.5708 0" />
<geometry>
<mesh filename="package://upperleg_3.stl"/>
</geometry>
<material name="upperleg_3_material">
<color rgba="0.917647 0.917647 0.917647 1.0"/>
</material>
</collision>
<visual>
<origin xyz="0.165 -0.00108365 -0.032916" rpy="1.5708 1.5708 0" />
<geometry>
<mesh filename="package://upperleg_11.stl"/>
</geometry>
<material name="upperleg_11_material">
<color rgba="0.917647 0.917647 0.917647 1.0"/>
</material>
</visual>
<collision>
<origin xyz="0.165 -0.00108365 -0.032916" rpy="1.5708 1.5708 0" />
<geometry>
<mesh filename="package://upperleg_11.stl"/>
</geometry>
<material name="upperleg_11_material">
<color rgba="0.917647 0.917647 0.917647 1.0"/>
</material>
</collision>
<visual>
<origin xyz="0.165 -0.00108365 -0.032916" rpy="1.5708 1.5708 0" />
<geometry>
<mesh filename="package://upperleg_5.stl"/>
</geometry>
<material name="upperleg_5_material">
<color rgba="0.917647 0.917647 0.917647 1.0"/>
</material>
</visual>
<collision>
<origin xyz="0.165 -0.00108365 -0.032916" rpy="1.5708 1.5708 0" />
<geometry>
<mesh filename="package://upperleg_5.stl"/>
</geometry>
<material name="upperleg_5_material">
<color rgba="0.917647 0.917647 0.917647 1.0"/>
</material>
</collision>
<visual>
<origin xyz="0.165 -0.00108365 -0.032916" rpy="1.5708 1.5708 0" />
<geometry>
<mesh filename="package://upperleg_6.stl"/>
</geometry>
<material name="upperleg_6_material">
<color rgba="0.917647 0.917647 0.917647 1.0"/>
</material>
</visual>
<collision>
<origin xyz="0.165 -0.00108365 -0.032916" rpy="1.5708 1.5708 0" />
<geometry>
<mesh filename="package://upperleg_6.stl"/>
</geometry>
<material name="upperleg_6_material">
<color rgba="0.917647 0.917647 0.917647 1.0"/>
</material>
</collision>
<visual>
<origin xyz="0.00843847 0.0124486 -0.028916" rpy="0.523599 1.5708 0" />
<geometry>
<mesh filename="package://motor9225v5_1.stl"/>
</geometry>
<material name="motor9225v5_1_material">
<color rgba="0.917647 0.917647 0.917647 1.0"/>
</material>
</visual>
<collision>
<origin xyz="0.00843847 0.0124486 -0.028916" rpy="0.523599 1.5708 0" />
<geometry>
<mesh filename="package://motor9225v5_1.stl"/>
</geometry>
<material name="motor9225v5_1_material">
<color rgba="0.917647 0.917647 0.917647 1.0"/>
</material>
</collision>
<visual>
<origin xyz="-0.0766619 -0.0781945 0.042084" rpy="0.785398 1.5708 0" />
<geometry>
<mesh filename="package://ams_1.stl"/>
</geometry>
<material name="ams_1_material">
<color rgba="0.917647 0.917647 0.917647 1.0"/>
</material>
</visual>
<collision>
<origin xyz="-0.0766619 -0.0781945 0.042084" rpy="0.785398 1.5708 0" />
<geometry>
<mesh filename="package://ams_1.stl"/>
</geometry>
<material name="ams_1_material">
<color rgba="0.917647 0.917647 0.917647 1.0"/>
</material>
</collision>
<visual>
<origin xyz="0.165 -0.00108365 -0.032916" rpy="1.5708 1.5708 0" />
<geometry>
<mesh filename="package://upperleg_8.stl"/>
</geometry>
<material name="upperleg_8_material">
<color rgba="0.917647 0.917647 0.917647 1.0"/>
</material>
</visual>
<collision>
<origin xyz="0.165 -0.00108365 -0.032916" rpy="1.5708 1.5708 0" />
<geometry>
<mesh filename="package://upperleg_8.stl"/>
</geometry>
<material name="upperleg_8_material">
<color rgba="0.917647 0.917647 0.917647 1.0"/>
</material>
</collision>
<inertial>
<origin xyz="-0.000592499 0.0567057 -0.043972" rpy="0 0 0"/>
<mass value="0.97" />
<inertia ixx="0.00309778" ixy="3.64215e-05"  ixz="2.28223e-05" iyy="0.00465531" iyz="-0.000182553" izz="0.00543222" />
</inertial>
</link>

<link name="lowerleg_4">
<visual>
<origin xyz="0.165 0.201084 -0.0325" rpy="-1.5708 -1.5708 0" />
<geometry>
<mesh filename="package://lowerleg_2.stl"/>
</geometry>
<material name="lowerleg_2_material">
<color rgba="0.615686 0.811765 0.929412 1.0"/>
</material>
</visual>
<collision>
<origin xyz="0.165 0.201084 -0.0325" rpy="-1.5708 -1.5708 0" />
<geometry>
<mesh filename="package://lowerleg_2.stl"/>
</geometry>
<material name="lowerleg_2_material">
<color rgba="0.615686 0.811765 0.929412 1.0"/>
</material>
</collision>
<visual>
<origin xyz="0.165 0.201084 -0.0325" rpy="-1.5708 -1.5708 0" />
<geometry>
<mesh filename="package://lowerleg_1.stl"/>
</geometry>
<material name="lowerleg_1_material">
<color rgba="0.615686 0.811765 0.929412 1.0"/>
</material>
</visual>
<collision>
<origin xyz="0.165 0.201084 -0.0325" rpy="-1.5708 -1.5708 0" />
<geometry>
<mesh filename="package://lowerleg_1.stl"/>
</geometry>
<material name="lowerleg_1_material">
<color rgba="0.615686 0.811765 0.929412 1.0"/>
</material>
</collision>
<visual>
<origin xyz="0.165 0.201084 -0.0325" rpy="-1.5708 -1.5708 0" />
<geometry>
<mesh filename="package://foot.stl"/>
</geometry>
<material name="foot_material">
<color rgba="0.815686 0.00392157 0.00392157 1.0"/>
</material>
</visual>
<collision>
<origin xyz="0.165 0.201084 -0.0325" rpy="-1.5708 -1.5708 0" />
<geometry>
<mesh filename="package://foot.stl"/>
</geometry>
<material name="foot_material">
<color rgba="0.815686 0.00392157 0.00392157 1.0"/>
</material>
</collision>
<visual>
<origin xyz="0.165 0.201114 -0.03229" rpy="-1.5708 -1.5708 0" />
<geometry>
<mesh filename="package://lowerleg_3.stl"/>
</geometry>
<material name="lowerleg_3_material">
<color rgba="0.615686 0.811765 0.929412 1.0"/>
</material>
</visual>
<collision>
<origin xyz="0.165 0.201114 -0.03229" rpy="-1.5708 -1.5708 0" />
<geometry>
<mesh filename="package://lowerleg_3.stl"/>
</geometry>
<material name="lowerleg_3_material">
<color rgba="0.615686 0.811765 0.929412 1.0"/>
</material>
</collision>
<inertial>
<origin xyz="2.76478e-06 -0.0634662 -0.0415243" rpy="0 0 0"/>
<mass value="0.34" />
<inertia ixx="0.0024225" ixy="-3.78677e-06"  ixz="5.33358e-08" iyy="0.00107662" iyz="-0.000776024" izz="0.00248712" />
</inertial>
</link>

<link name="foot_br">
<inertial>
<origin xyz="0 0 0" rpy="0 0 0" />
<mass value="1e-9" />
<inertia ixx="0" ixy="0" ixz="0" iyy="0" iyz="0" izz="0" />
</inertial>
</link>
<joint name="foot_br_frame" type="fixed">
<origin xyz="1.44661e-05 -0.195916 -0.0978296" rpy="-1.5708 1.5708 0" />
<parent link="lowerleg_4" />
<child link="foot_br" />
<axis xyz="0 0 0"/>
</joint>

<joint name="ankle_br" type="revolute">
<origin xyz="-4.05231e-15 0.2 -0.065516" rpy="3.14159 -4.48145e-15 -9.21485e-15" />
<parent link="upperleg_4" />
<child link="lowerleg_4" />
<axis xyz="0 0 1"/>
<limit effort="1" velocity="20" lower="-2.35619" upper="2.35619"/>
<joint_properties friction="0.0"/>
</joint>

<joint name="knee_br" type="revolute">
<origin xyz="0.0319278 -1.83141e-07 0.1815" rpy="3.14159 1.5708 0" />
<parent link="hip_2" />
<child link="upperleg_4" />
<axis xyz="0 0 1"/>
<limit effort="1" velocity="20" lower="-0.872665" upper="0.698132"/>
<joint_properties friction="0.0"/>
</joint>

<joint name="hip_br" type="revolute">
<origin xyz="-0.126016 0.0833899 0.0733429" rpy="1.5708 -4.75723e-14 -3.14159" />
<parent link="body" />
<child link="hip_2" />
<axis xyz="0 0 1"/>
<limit effort="1" velocity="20" lower="-0.523599" upper="1.39626"/>
<joint_properties friction="0.0"/>
</joint>


</robot>
